2022-04-09 00:30:41,627 [INFO] 13024 19584 C:\Users\vanis\.virtualenvs\manager_api-qKfrZB-Q\lib\site-packages\django\utils\autoreload.py:617 Watching for file changes with StatReloader
2022-04-09 00:30:49,111 [INFO] 13024 3180 C:\Users\vanis\OneDrive\デスクトップ\workspace\03_projects\01_private\manager\manager_api\manager_api_app\views\body_weight_view.py:19 log info test!
2022-04-09 00:30:49,111 [ERROR] 13024 3180 C:\Users\vanis\OneDrive\デスクトップ\workspace\03_projects\01_private\manager\manager_api\manager_api_app\views\body_weight_view.py:20 log error test!
2022-04-09 00:30:49,117 [INFO] 13024 3180 C:\Users\vanis\.virtualenvs\manager_api-qKfrZB-Q\lib\site-packages\django\core\servers\basehttp.py:157 "GET /manager_api_app/history_user/ HTTP/1.1" 200 89
2022-04-09 00:34:16,393 [INFO] 13024 19584 C:\Users\vanis\.virtualenvs\manager_api-qKfrZB-Q\lib\site-packages\django\utils\autoreload.py:240 C:\Users\vanis\OneDrive\デスクトップ\workspace\03_projects\01_private\manager\manager_api\manager_api\settings\base.py changed, reloading.
2022-04-09 00:34:17,047 [INFO] 22616 23280 C:\Users\vanis\.virtualenvs\manager_api-qKfrZB-Q\lib\site-packages\django\utils\autoreload.py:617 Watching for file changes with StatReloader
2022-04-09 00:34:43,485 [INFO] 22616 23280 C:\Users\vanis\.virtualenvs\manager_api-qKfrZB-Q\lib\site-packages\django\utils\autoreload.py:240 C:\Users\vanis\OneDrive\デスクトップ\workspace\03_projects\01_private\manager\manager_api\manager_api_app\views\body_weight_view.py changed, reloading.
2022-04-09 00:34:44,170 [INFO] 21292 14896 C:\Users\vanis\.virtualenvs\manager_api-qKfrZB-Q\lib\site-packages\django\utils\autoreload.py:617 Watching for file changes with StatReloader
2022-04-09 00:34:46,918 [INFO] 21292 23964 C:\Users\vanis\OneDrive\デスクトップ\workspace\03_projects\01_private\manager\manager_api\manager_api_app\views\body_weight_view.py:20 [{'users': 'tetsuya'}, {'users': 'taro'}]
2022-04-09 00:34:46,918 [ERROR] 21292 23964 C:\Users\vanis\OneDrive\デスクトップ\workspace\03_projects\01_private\manager\manager_api\manager_api_app\views\body_weight_view.py:21 log error test!
2022-04-09 00:34:46,920 [INFO] 21292 23964 C:\Users\vanis\.virtualenvs\manager_api-qKfrZB-Q\lib\site-packages\django\core\servers\basehttp.py:157 "GET /manager_api_app/history_user/ HTTP/1.1" 200 89
2022-04-09 00:34:53,623 [INFO] 21292 23964 C:\Users\vanis\OneDrive\デスクトップ\workspace\03_projects\01_private\manager\manager_api\manager_api_app\views\body_weight_view.py:20 [{'users': 'tetsuya'}, {'users': 'taro'}]
2022-04-09 00:34:53,624 [ERROR] 21292 23964 C:\Users\vanis\OneDrive\デスクトップ\workspace\03_projects\01_private\manager\manager_api\manager_api_app\views\body_weight_view.py:21 log error test!
2022-04-09 00:34:53,624 [INFO] 21292 23964 C:\Users\vanis\.virtualenvs\manager_api-qKfrZB-Q\lib\site-packages\django\core\servers\basehttp.py:157 "GET /manager_api_app/history_user/ HTTP/1.1" 200 89
2022-04-09 00:36:53,140 [INFO] 21292 14896 C:\Users\vanis\.virtualenvs\manager_api-qKfrZB-Q\lib\site-packages\django\utils\autoreload.py:240 C:\Users\vanis\OneDrive\デスクトップ\workspace\03_projects\01_private\manager\manager_api\manager_api_app\views\body_weight_view.py changed, reloading.
2022-04-09 00:36:53,850 [INFO] 11936 13300 C:\Users\vanis\.virtualenvs\manager_api-qKfrZB-Q\lib\site-packages\django\utils\autoreload.py:617 Watching for file changes with StatReloader
2022-04-09 00:36:59,167 [ERROR] 11936 8080 C:\Users\vanis\.virtualenvs\manager_api-qKfrZB-Q\lib\site-packages\django\utils\log.py:224 Internal Server Error: /manager_api_app/history_user/
Traceback (most recent call last):
  File "C:\Users\vanis\.virtualenvs\manager_api-qKfrZB-Q\lib\site-packages\django\core\handlers\exception.py", line 47, in inner
    response = get_response(request)
  File "C:\Users\vanis\.virtualenvs\manager_api-qKfrZB-Q\lib\site-packages\django\core\handlers\base.py", line 181, in _get_response
    response = wrapped_callback(request, *callback_args, **callback_kwargs)
  File "C:\Users\vanis\.virtualenvs\manager_api-qKfrZB-Q\lib\site-packages\django\views\decorators\csrf.py", line 54, in wrapped_view
    return view_func(*args, **kwargs)
  File "C:\Users\vanis\.virtualenvs\manager_api-qKfrZB-Q\lib\site-packages\django\views\generic\base.py", line 70, in view
    return self.dispatch(request, *args, **kwargs)
  File "C:\Users\vanis\.virtualenvs\manager_api-qKfrZB-Q\lib\site-packages\rest_framework\views.py", line 509, in dispatch
    response = self.handle_exception(exc)
  File "C:\Users\vanis\.virtualenvs\manager_api-qKfrZB-Q\lib\site-packages\rest_framework\views.py", line 469, in handle_exception
    self.raise_uncaught_exception(exc)
  File "C:\Users\vanis\.virtualenvs\manager_api-qKfrZB-Q\lib\site-packages\rest_framework\views.py", line 480, in raise_uncaught_exception
    raise exc
  File "C:\Users\vanis\.virtualenvs\manager_api-qKfrZB-Q\lib\site-packages\rest_framework\views.py", line 506, in dispatch
    response = handler(request, *args, **kwargs)
  File "C:\Users\vanis\.virtualenvs\manager_api-qKfrZB-Q\lib\site-packages\rest_framework\decorators.py", line 50, in handler
    return func(*args, **kwargs)
  File "C:\Users\vanis\OneDrive\デスクトップ\workspace\03_projects\01_private\manager\manager_api\manager_api_app\views\body_weight_view.py", line 21, in get_user
    logger.info(result_data)
AttributeError: 'StreamHandler' object has no attribute 'info'
2022-04-09 00:36:59,169 [ERROR] 11936 8080 C:\Users\vanis\.virtualenvs\manager_api-qKfrZB-Q\lib\site-packages\django\core\servers\basehttp.py:157 "GET /manager_api_app/history_user/ HTTP/1.1" 500 100256
2022-04-09 00:38:02,411 [INFO] 11936 13300 C:\Users\vanis\.virtualenvs\manager_api-qKfrZB-Q\lib\site-packages\django\utils\autoreload.py:240 C:\Users\vanis\OneDrive\デスクトップ\workspace\03_projects\01_private\manager\manager_api\manager_api_app\views\body_weight_view.py changed, reloading.
2022-04-09 00:38:03,104 [INFO] 15628 11252 C:\Users\vanis\.virtualenvs\manager_api-qKfrZB-Q\lib\site-packages\django\utils\autoreload.py:617 Watching for file changes with StatReloader
2022-04-09 00:38:46,285 [INFO] 15628 11252 C:\Users\vanis\.virtualenvs\manager_api-qKfrZB-Q\lib\site-packages\django\utils\autoreload.py:240 C:\Users\vanis\OneDrive\デスクトップ\workspace\03_projects\01_private\manager\manager_api\manager_api\settings\base.py changed, reloading.
2022-04-09 00:39:04,162 [INFO] 18324 23736 C:\Users\vanis\.virtualenvs\manager_api-qKfrZB-Q\lib\site-packages\django\utils\autoreload.py:617 Watching for file changes with StatReloader
2022-04-09 00:39:56,509 [INFO] 18324 23736 C:\Users\vanis\.virtualenvs\manager_api-qKfrZB-Q\lib\site-packages\django\utils\autoreload.py:240 C:\Users\vanis\OneDrive\デスクトップ\workspace\03_projects\01_private\manager\manager_api\manager_api\settings\base.py changed, reloading.
2022-04-09 00:39:57,224 [INFO] 16780 16916 C:\Users\vanis\.virtualenvs\manager_api-qKfrZB-Q\lib\site-packages\django\utils\autoreload.py:617 Watching for file changes with StatReloader
2022-04-09 00:42:13,000 [INFO] 16780 16916 C:\Users\vanis\.virtualenvs\manager_api-qKfrZB-Q\lib\site-packages\django\utils\autoreload.py:240 C:\Users\vanis\OneDrive\デスクトップ\workspace\03_projects\01_private\manager\manager_api\manager_api\settings\base.py changed, reloading.
2022-04-09 00:42:13,704 [INFO] 9144 8364 C:\Users\vanis\.virtualenvs\manager_api-qKfrZB-Q\lib\site-packages\django\utils\autoreload.py:617 Watching for file changes with StatReloader
2022-04-09 00:42:23,401 [INFO] 9144 8364 C:\Users\vanis\.virtualenvs\manager_api-qKfrZB-Q\lib\site-packages\django\utils\autoreload.py:240 C:\Users\vanis\OneDrive\デスクトップ\workspace\03_projects\01_private\manager\manager_api\manager_api_app\views\body_weight_view.py changed, reloading.
2022-04-09 00:42:24,180 [INFO] 16936 12304 C:\Users\vanis\.virtualenvs\manager_api-qKfrZB-Q\lib\site-packages\django\utils\autoreload.py:617 Watching for file changes with StatReloader
2022-04-09 00:42:31,614 [INFO] 16936 24360 C:\Users\vanis\OneDrive\デスクトップ\workspace\03_projects\01_private\manager\manager_api\manager_api_app\views\body_weight_view.py:20 [{'users': 'tetsuya'}, {'users': 'taro'}]
2022-04-09 00:42:31,615 [ERROR] 16936 24360 C:\Users\vanis\OneDrive\デスクトップ\workspace\03_projects\01_private\manager\manager_api\manager_api_app\views\body_weight_view.py:21 log error test!
2022-04-09 00:42:31,617 [INFO] 16936 24360 C:\Users\vanis\.virtualenvs\manager_api-qKfrZB-Q\lib\site-packages\django\core\servers\basehttp.py:157 "GET /manager_api_app/history_user/ HTTP/1.1" 200 89
2022-04-09 00:43:14,747 [INFO] 16936 12304 C:\Users\vanis\.virtualenvs\manager_api-qKfrZB-Q\lib\site-packages\django\utils\autoreload.py:240 C:\Users\vanis\OneDrive\デスクトップ\workspace\03_projects\01_private\manager\manager_api\manager_api_app\views\body_weight_view.py changed, reloading.
2022-04-09 00:43:15,462 [INFO] 9764 2240 C:\Users\vanis\.virtualenvs\manager_api-qKfrZB-Q\lib\site-packages\django\utils\autoreload.py:617 Watching for file changes with StatReloader
2022-04-09 00:43:30,242 [INFO] 9764 14784 C:\Users\vanis\OneDrive\デスクトップ\workspace\03_projects\01_private\manager\manager_api\manager_api_app\views\body_weight_view.py:20 [{'users': 'tetsuya'}, {'users': 'taro'}]
2022-04-09 00:43:30,243 [ERROR] 9764 14784 C:\Users\vanis\OneDrive\デスクトップ\workspace\03_projects\01_private\manager\manager_api\manager_api_app\views\body_weight_view.py:21 log error test!
2022-04-09 00:43:30,246 [INFO] 9764 14784 C:\Users\vanis\.virtualenvs\manager_api-qKfrZB-Q\lib\site-packages\django\core\servers\basehttp.py:157 "GET /manager_api_app/history_user/ HTTP/1.1" 200 89
2022-04-09 00:43:33,680 [INFO] 9764 14784 C:\Users\vanis\OneDrive\デスクトップ\workspace\03_projects\01_private\manager\manager_api\manager_api_app\views\body_weight_view.py:20 [{'users': 'tetsuya'}, {'users': 'taro'}]
2022-04-09 00:43:33,681 [ERROR] 9764 14784 C:\Users\vanis\OneDrive\デスクトップ\workspace\03_projects\01_private\manager\manager_api\manager_api_app\views\body_weight_view.py:21 log error test!
2022-04-09 00:43:33,682 [INFO] 9764 14784 C:\Users\vanis\.virtualenvs\manager_api-qKfrZB-Q\lib\site-packages\django\core\servers\basehttp.py:157 "GET /manager_api_app/history_user/ HTTP/1.1" 200 89
2022-04-09 00:47:46,885 [INFO] 9764 2240 C:\Users\vanis\.virtualenvs\manager_api-qKfrZB-Q\lib\site-packages\django\utils\autoreload.py:240 C:\Users\vanis\OneDrive\デスクトップ\workspace\03_projects\01_private\manager\manager_api\manager_api\settings\base.py changed, reloading.
2022-04-09 00:47:47,561 [INFO] 19540 21652 C:\Users\vanis\.virtualenvs\manager_api-qKfrZB-Q\lib\site-packages\django\utils\autoreload.py:617 Watching for file changes with StatReloader
2022-04-09 00:48:36,883 [INFO] 19540 21652 C:\Users\vanis\.virtualenvs\manager_api-qKfrZB-Q\lib\site-packages\django\utils\autoreload.py:240 C:\Users\vanis\OneDrive\デスクトップ\workspace\03_projects\01_private\manager\manager_api\manager_api_app\views\body_weight_view.py changed, reloading.
2022-04-09 00:48:37,572 [INFO] 23404 13864 C:\Users\vanis\.virtualenvs\manager_api-qKfrZB-Q\lib\site-packages\django\utils\autoreload.py:617 Watching for file changes with StatReloader
2022-04-09 00:50:26,487 [INFO] 23404 13864 C:\Users\vanis\.virtualenvs\manager_api-qKfrZB-Q\lib\site-packages\django\utils\autoreload.py:240 C:\Users\vanis\OneDrive\デスクトップ\workspace\03_projects\01_private\manager\manager_api\manager_api_app\views\body_weight_view.py changed, reloading.
2022-04-09 00:50:27,150 [INFO] 22128 5324 C:\Users\vanis\.virtualenvs\manager_api-qKfrZB-Q\lib\site-packages\django\utils\autoreload.py:617 Watching for file changes with StatReloader
2022-04-09 00:50:31,329 [INFO] 22128 2000 C:\Users\vanis\OneDrive\デスクトップ\workspace\03_projects\01_private\manager\manager_api\manager_api_app\views\body_weight_view.py:21 [{'users': 'tetsuya'}, {'users': 'taro'}]
2022-04-09 00:50:31,330 [ERROR] 22128 2000 C:\Users\vanis\OneDrive\デスクトップ\workspace\03_projects\01_private\manager\manager_api\manager_api_app\views\body_weight_view.py:22 log error test!
2022-04-09 00:50:31,332 [INFO] 22128 2000 C:\Users\vanis\.virtualenvs\manager_api-qKfrZB-Q\lib\site-packages\django\core\servers\basehttp.py:157 "GET /manager_api_app/history_user/ HTTP/1.1" 200 89
2022-04-09 00:50:59,045 [INFO] 22128 2000 C:\Users\vanis\.virtualenvs\manager_api-qKfrZB-Q\lib\site-packages\django\core\servers\basehttp.py:157 "OPTIONS /manager_api_app/body_weight/ HTTP/1.1" 200 0
2022-04-09 00:50:59,496 [ERROR] 22128 15672 C:\Users\vanis\.virtualenvs\manager_api-qKfrZB-Q\lib\site-packages\django\utils\log.py:224 Internal Server Error: /manager_api_app/body_weight/
Traceback (most recent call last):
  File "C:\Users\vanis\.virtualenvs\manager_api-qKfrZB-Q\lib\site-packages\rest_framework\request.py", line 416, in __getattr__
    return getattr(self._request, attr)
AttributeError: 'WSGIRequest' object has no attribute 'user_name'

During handling of the above exception, another exception occurred:

Traceback (most recent call last):
  File "C:\Users\vanis\.virtualenvs\manager_api-qKfrZB-Q\lib\site-packages\django\core\handlers\exception.py", line 47, in inner
    response = get_response(request)
  File "C:\Users\vanis\.virtualenvs\manager_api-qKfrZB-Q\lib\site-packages\django\core\handlers\base.py", line 181, in _get_response
    response = wrapped_callback(request, *callback_args, **callback_kwargs)
  File "C:\Users\vanis\.virtualenvs\manager_api-qKfrZB-Q\lib\site-packages\django\views\decorators\csrf.py", line 54, in wrapped_view
    return view_func(*args, **kwargs)
  File "C:\Users\vanis\.virtualenvs\manager_api-qKfrZB-Q\lib\site-packages\django\views\generic\base.py", line 70, in view
    return self.dispatch(request, *args, **kwargs)
  File "C:\Users\vanis\.virtualenvs\manager_api-qKfrZB-Q\lib\site-packages\rest_framework\views.py", line 509, in dispatch
    response = self.handle_exception(exc)
  File "C:\Users\vanis\.virtualenvs\manager_api-qKfrZB-Q\lib\site-packages\rest_framework\views.py", line 469, in handle_exception
    self.raise_uncaught_exception(exc)
  File "C:\Users\vanis\.virtualenvs\manager_api-qKfrZB-Q\lib\site-packages\rest_framework\views.py", line 480, in raise_uncaught_exception
    raise exc
  File "C:\Users\vanis\.virtualenvs\manager_api-qKfrZB-Q\lib\site-packages\rest_framework\views.py", line 506, in dispatch
    response = handler(request, *args, **kwargs)
  File "C:\Users\vanis\.virtualenvs\manager_api-qKfrZB-Q\lib\site-packages\rest_framework\decorators.py", line 50, in handler
    return func(*args, **kwargs)
  File "C:\Users\vanis\OneDrive\デスクトップ\workspace\03_projects\01_private\manager\manager_api\manager_api_app\views\body_weight_view.py", line 34, in get_weight
    weight_list = BodyWeight.objects.get(users=request.user_name, delete_flag=0)
  File "C:\Users\vanis\.virtualenvs\manager_api-qKfrZB-Q\lib\site-packages\rest_framework\request.py", line 418, in __getattr__
    return self.__getattribute__(attr)
AttributeError: 'Request' object has no attribute 'user_name'
2022-04-09 00:50:59,501 [ERROR] 22128 15672 C:\Users\vanis\.virtualenvs\manager_api-qKfrZB-Q\lib\site-packages\django\core\servers\basehttp.py:157 "POST /manager_api_app/body_weight/ HTTP/1.1" 500 108235
2022-06-04 14:49:50,920 [INFO] 1240 22168 C:\Users\vanis\.virtualenvs\manager_api-qKfrZB-Q\lib\site-packages\django\utils\autoreload.py:617 Watching for file changes with StatReloader
2022-06-04 14:50:04,189 [INFO] 22992 13508 C:\Users\vanis\.virtualenvs\manager_api-qKfrZB-Q\lib\site-packages\django\utils\autoreload.py:617 Watching for file changes with StatReloader
2022-06-04 14:50:08,329 [INFO] 22992 20716 C:\Users\vanis\OneDrive\デスクトップ\workspace\03_projects\01_private\manager\manager_api\manager_api_app\views\body_weight_view.py:21 [{'users': 'tetsuya'}, {'users': 'taro'}]
2022-06-04 14:50:08,331 [ERROR] 22992 20716 C:\Users\vanis\OneDrive\デスクトップ\workspace\03_projects\01_private\manager\manager_api\manager_api_app\views\body_weight_view.py:22 log error test!
2022-06-04 14:50:08,332 [INFO] 22992 20716 C:\Users\vanis\.virtualenvs\manager_api-qKfrZB-Q\lib\site-packages\django\core\servers\basehttp.py:157 "GET /manager_api_app/history_user/ HTTP/1.1" 200 89
2022-06-04 14:50:11,040 [INFO] 22992 20716 C:\Users\vanis\OneDrive\デスクトップ\workspace\03_projects\01_private\manager\manager_api\manager_api_app\views\body_weight_view.py:21 [{'users': 'tetsuya'}, {'users': 'taro'}]
2022-06-04 14:50:11,041 [ERROR] 22992 20716 C:\Users\vanis\OneDrive\デスクトップ\workspace\03_projects\01_private\manager\manager_api\manager_api_app\views\body_weight_view.py:22 log error test!
2022-06-04 14:50:11,042 [INFO] 22992 20716 C:\Users\vanis\.virtualenvs\manager_api-qKfrZB-Q\lib\site-packages\django\core\servers\basehttp.py:157 "GET /manager_api_app/history_user/ HTTP/1.1" 200 89
2022-06-04 14:50:12,502 [INFO] 22992 20716 C:\Users\vanis\.virtualenvs\manager_api-qKfrZB-Q\lib\site-packages\django\core\servers\basehttp.py:157 "OPTIONS /manager_api_app/body_weight/ HTTP/1.1" 200 0
2022-06-04 14:50:14,286 [ERROR] 22992 15396 C:\Users\vanis\.virtualenvs\manager_api-qKfrZB-Q\lib\site-packages\django\utils\log.py:224 Internal Server Error: /manager_api_app/body_weight/
Traceback (most recent call last):
  File "C:\Users\vanis\.virtualenvs\manager_api-qKfrZB-Q\lib\site-packages\rest_framework\request.py", line 416, in __getattr__
    return getattr(self._request, attr)
AttributeError: 'WSGIRequest' object has no attribute 'user_name'

During handling of the above exception, another exception occurred:

Traceback (most recent call last):
  File "C:\Users\vanis\.virtualenvs\manager_api-qKfrZB-Q\lib\site-packages\django\core\handlers\exception.py", line 47, in inner
    response = get_response(request)
  File "C:\Users\vanis\.virtualenvs\manager_api-qKfrZB-Q\lib\site-packages\django\core\handlers\base.py", line 181, in _get_response
    response = wrapped_callback(request, *callback_args, **callback_kwargs)
  File "C:\Users\vanis\.virtualenvs\manager_api-qKfrZB-Q\lib\site-packages\django\views\decorators\csrf.py", line 54, in wrapped_view
    return view_func(*args, **kwargs)
  File "C:\Users\vanis\.virtualenvs\manager_api-qKfrZB-Q\lib\site-packages\django\views\generic\base.py", line 70, in view
    return self.dispatch(request, *args, **kwargs)
  File "C:\Users\vanis\.virtualenvs\manager_api-qKfrZB-Q\lib\site-packages\rest_framework\views.py", line 509, in dispatch
    response = self.handle_exception(exc)
  File "C:\Users\vanis\.virtualenvs\manager_api-qKfrZB-Q\lib\site-packages\rest_framework\views.py", line 469, in handle_exception
    self.raise_uncaught_exception(exc)
  File "C:\Users\vanis\.virtualenvs\manager_api-qKfrZB-Q\lib\site-packages\rest_framework\views.py", line 480, in raise_uncaught_exception
    raise exc
  File "C:\Users\vanis\.virtualenvs\manager_api-qKfrZB-Q\lib\site-packages\rest_framework\views.py", line 506, in dispatch
    response = handler(request, *args, **kwargs)
  File "C:\Users\vanis\.virtualenvs\manager_api-qKfrZB-Q\lib\site-packages\rest_framework\decorators.py", line 50, in handler
    return func(*args, **kwargs)
  File "C:\Users\vanis\OneDrive\デスクトップ\workspace\03_projects\01_private\manager\manager_api\manager_api_app\views\body_weight_view.py", line 34, in get_weight
    weight_list = BodyWeight.objects.get(users=request.user_name, delete_flag=0)
  File "C:\Users\vanis\.virtualenvs\manager_api-qKfrZB-Q\lib\site-packages\rest_framework\request.py", line 418, in __getattr__
    return self.__getattribute__(attr)
AttributeError: 'Request' object has no attribute 'user_name'
2022-06-04 14:50:14,290 [ERROR] 22992 15396 C:\Users\vanis\.virtualenvs\manager_api-qKfrZB-Q\lib\site-packages\django\core\servers\basehttp.py:157 "POST /manager_api_app/body_weight/ HTTP/1.1" 500 109395
2022-06-04 14:50:33,809 [INFO] 22992 13508 C:\Users\vanis\.virtualenvs\manager_api-qKfrZB-Q\lib\site-packages\django\utils\autoreload.py:240 C:\Users\vanis\OneDrive\デスクトップ\workspace\03_projects\01_private\manager\manager_api\manager_api\settings\base.py changed, reloading.
2022-06-04 14:50:34,501 [INFO] 10232 19640 C:\Users\vanis\.virtualenvs\manager_api-qKfrZB-Q\lib\site-packages\django\utils\autoreload.py:617 Watching for file changes with StatReloader
2022-06-04 14:54:51,671 [INFO] 10232 22448 C:\Users\vanis\OneDrive\デスクトップ\workspace\03_projects\01_private\manager\manager_api\manager_api_app\views\body_weight_view.py:21 [{'users': 'tetsuya'}, {'users': 'taro'}]
2022-06-04 14:54:51,671 [ERROR] 10232 22448 C:\Users\vanis\OneDrive\デスクトップ\workspace\03_projects\01_private\manager\manager_api\manager_api_app\views\body_weight_view.py:22 log error test!
2022-06-04 14:54:51,673 [INFO] 10232 22448 C:\Users\vanis\.virtualenvs\manager_api-qKfrZB-Q\lib\site-packages\django\core\servers\basehttp.py:157 "GET /manager_api_app/history_user/ HTTP/1.1" 200 89
2022-06-04 14:56:44,337 [INFO] 10232 22448 C:\Users\vanis\OneDrive\デスクトップ\workspace\03_projects\01_private\manager\manager_api\manager_api_app\views\body_weight_view.py:21 [{'users': 'tetsuya'}, {'users': 'taro'}]
2022-06-04 14:56:44,337 [ERROR] 10232 22448 C:\Users\vanis\OneDrive\デスクトップ\workspace\03_projects\01_private\manager\manager_api\manager_api_app\views\body_weight_view.py:22 log error test!
2022-06-04 14:56:44,338 [INFO] 10232 22448 C:\Users\vanis\.virtualenvs\manager_api-qKfrZB-Q\lib\site-packages\django\core\servers\basehttp.py:157 "GET /manager_api_app/history_user/ HTTP/1.1" 200 89
2022-06-04 15:09:56,777 [INFO] 10232 19392 C:\Users\vanis\OneDrive\デスクトップ\workspace\03_projects\01_private\manager\manager_api\manager_api_app\views\body_weight_view.py:21 [{'users': 'tetsuya'}, {'users': 'taro'}]
2022-06-04 15:09:56,780 [ERROR] 10232 19392 C:\Users\vanis\OneDrive\デスクトップ\workspace\03_projects\01_private\manager\manager_api\manager_api_app\views\body_weight_view.py:22 log error test!
2022-06-04 15:09:56,782 [INFO] 10232 19392 C:\Users\vanis\.virtualenvs\manager_api-qKfrZB-Q\lib\site-packages\django\core\servers\basehttp.py:157 "GET /manager_api_app/history_user/ HTTP/1.1" 200 89
2022-06-04 15:09:56,847 [ERROR] 10232 18112 C:\Users\vanis\.virtualenvs\manager_api-qKfrZB-Q\lib\site-packages\django\utils\log.py:224 Internal Server Error: /manager_api_app/body_weight/
Traceback (most recent call last):
  File "C:\Users\vanis\.virtualenvs\manager_api-qKfrZB-Q\lib\site-packages\rest_framework\request.py", line 416, in __getattr__
    return getattr(self._request, attr)
AttributeError: 'WSGIRequest' object has no attribute 'user_name'

During handling of the above exception, another exception occurred:

Traceback (most recent call last):
  File "C:\Users\vanis\.virtualenvs\manager_api-qKfrZB-Q\lib\site-packages\django\core\handlers\exception.py", line 47, in inner
    response = get_response(request)
  File "C:\Users\vanis\.virtualenvs\manager_api-qKfrZB-Q\lib\site-packages\django\core\handlers\base.py", line 181, in _get_response
    response = wrapped_callback(request, *callback_args, **callback_kwargs)
  File "C:\Users\vanis\.virtualenvs\manager_api-qKfrZB-Q\lib\site-packages\django\views\decorators\csrf.py", line 54, in wrapped_view
    return view_func(*args, **kwargs)
  File "C:\Users\vanis\.virtualenvs\manager_api-qKfrZB-Q\lib\site-packages\django\views\generic\base.py", line 70, in view
    return self.dispatch(request, *args, **kwargs)
  File "C:\Users\vanis\.virtualenvs\manager_api-qKfrZB-Q\lib\site-packages\rest_framework\views.py", line 509, in dispatch
    response = self.handle_exception(exc)
  File "C:\Users\vanis\.virtualenvs\manager_api-qKfrZB-Q\lib\site-packages\rest_framework\views.py", line 469, in handle_exception
    self.raise_uncaught_exception(exc)
  File "C:\Users\vanis\.virtualenvs\manager_api-qKfrZB-Q\lib\site-packages\rest_framework\views.py", line 480, in raise_uncaught_exception
    raise exc
  File "C:\Users\vanis\.virtualenvs\manager_api-qKfrZB-Q\lib\site-packages\rest_framework\views.py", line 506, in dispatch
    response = handler(request, *args, **kwargs)
  File "C:\Users\vanis\.virtualenvs\manager_api-qKfrZB-Q\lib\site-packages\rest_framework\decorators.py", line 50, in handler
    return func(*args, **kwargs)
  File "C:\Users\vanis\OneDrive\デスクトップ\workspace\03_projects\01_private\manager\manager_api\manager_api_app\views\body_weight_view.py", line 34, in get_weight
    weight_list = BodyWeight.objects.get(users=request.user_name, delete_flag=0)
  File "C:\Users\vanis\.virtualenvs\manager_api-qKfrZB-Q\lib\site-packages\rest_framework\request.py", line 418, in __getattr__
    return self.__getattribute__(attr)
AttributeError: 'Request' object has no attribute 'user_name'
2022-06-04 15:09:56,852 [ERROR] 10232 18112 C:\Users\vanis\.virtualenvs\manager_api-qKfrZB-Q\lib\site-packages\django\core\servers\basehttp.py:157 "POST /manager_api_app/body_weight/ HTTP/1.1" 500 109395
2022-06-04 15:10:00,281 [INFO] 10232 19392 C:\Users\vanis\OneDrive\デスクトップ\workspace\03_projects\01_private\manager\manager_api\manager_api_app\views\body_weight_view.py:21 [{'users': 'tetsuya'}, {'users': 'taro'}]
2022-06-04 15:10:00,281 [ERROR] 10232 19392 C:\Users\vanis\OneDrive\デスクトップ\workspace\03_projects\01_private\manager\manager_api\manager_api_app\views\body_weight_view.py:22 log error test!
2022-06-04 15:10:00,283 [INFO] 10232 19392 C:\Users\vanis\.virtualenvs\manager_api-qKfrZB-Q\lib\site-packages\django\core\servers\basehttp.py:157 "GET /manager_api_app/history_user/ HTTP/1.1" 200 89
2022-06-04 15:10:00,302 [ERROR] 10232 18112 C:\Users\vanis\.virtualenvs\manager_api-qKfrZB-Q\lib\site-packages\django\utils\log.py:224 Internal Server Error: /manager_api_app/body_weight/
Traceback (most recent call last):
  File "C:\Users\vanis\.virtualenvs\manager_api-qKfrZB-Q\lib\site-packages\rest_framework\request.py", line 416, in __getattr__
    return getattr(self._request, attr)
AttributeError: 'WSGIRequest' object has no attribute 'user_name'

During handling of the above exception, another exception occurred:

Traceback (most recent call last):
  File "C:\Users\vanis\.virtualenvs\manager_api-qKfrZB-Q\lib\site-packages\django\core\handlers\exception.py", line 47, in inner
    response = get_response(request)
  File "C:\Users\vanis\.virtualenvs\manager_api-qKfrZB-Q\lib\site-packages\django\core\handlers\base.py", line 181, in _get_response
    response = wrapped_callback(request, *callback_args, **callback_kwargs)
  File "C:\Users\vanis\.virtualenvs\manager_api-qKfrZB-Q\lib\site-packages\django\views\decorators\csrf.py", line 54, in wrapped_view
    return view_func(*args, **kwargs)
  File "C:\Users\vanis\.virtualenvs\manager_api-qKfrZB-Q\lib\site-packages\django\views\generic\base.py", line 70, in view
    return self.dispatch(request, *args, **kwargs)
  File "C:\Users\vanis\.virtualenvs\manager_api-qKfrZB-Q\lib\site-packages\rest_framework\views.py", line 509, in dispatch
    response = self.handle_exception(exc)
  File "C:\Users\vanis\.virtualenvs\manager_api-qKfrZB-Q\lib\site-packages\rest_framework\views.py", line 469, in handle_exception
    self.raise_uncaught_exception(exc)
  File "C:\Users\vanis\.virtualenvs\manager_api-qKfrZB-Q\lib\site-packages\rest_framework\views.py", line 480, in raise_uncaught_exception
    raise exc
  File "C:\Users\vanis\.virtualenvs\manager_api-qKfrZB-Q\lib\site-packages\rest_framework\views.py", line 506, in dispatch
    response = handler(request, *args, **kwargs)
  File "C:\Users\vanis\.virtualenvs\manager_api-qKfrZB-Q\lib\site-packages\rest_framework\decorators.py", line 50, in handler
    return func(*args, **kwargs)
  File "C:\Users\vanis\OneDrive\デスクトップ\workspace\03_projects\01_private\manager\manager_api\manager_api_app\views\body_weight_view.py", line 34, in get_weight
    weight_list = BodyWeight.objects.get(users=request.user_name, delete_flag=0)
  File "C:\Users\vanis\.virtualenvs\manager_api-qKfrZB-Q\lib\site-packages\rest_framework\request.py", line 418, in __getattr__
    return self.__getattribute__(attr)
AttributeError: 'Request' object has no attribute 'user_name'
2022-06-04 15:10:00,307 [ERROR] 10232 18112 C:\Users\vanis\.virtualenvs\manager_api-qKfrZB-Q\lib\site-packages\django\core\servers\basehttp.py:157 "POST /manager_api_app/body_weight/ HTTP/1.1" 500 109395
2022-06-04 15:10:02,374 [INFO] 10232 19392 C:\Users\vanis\OneDrive\デスクトップ\workspace\03_projects\01_private\manager\manager_api\manager_api_app\views\body_weight_view.py:21 [{'users': 'tetsuya'}, {'users': 'taro'}]
2022-06-04 15:10:02,375 [ERROR] 10232 19392 C:\Users\vanis\OneDrive\デスクトップ\workspace\03_projects\01_private\manager\manager_api\manager_api_app\views\body_weight_view.py:22 log error test!
2022-06-04 15:10:02,376 [INFO] 10232 19392 C:\Users\vanis\.virtualenvs\manager_api-qKfrZB-Q\lib\site-packages\django\core\servers\basehttp.py:157 "GET /manager_api_app/history_user/ HTTP/1.1" 200 89
2022-06-04 15:10:02,394 [ERROR] 10232 18112 C:\Users\vanis\.virtualenvs\manager_api-qKfrZB-Q\lib\site-packages\django\utils\log.py:224 Internal Server Error: /manager_api_app/body_weight/
Traceback (most recent call last):
  File "C:\Users\vanis\.virtualenvs\manager_api-qKfrZB-Q\lib\site-packages\rest_framework\request.py", line 416, in __getattr__
    return getattr(self._request, attr)
AttributeError: 'WSGIRequest' object has no attribute 'user_name'

During handling of the above exception, another exception occurred:

Traceback (most recent call last):
  File "C:\Users\vanis\.virtualenvs\manager_api-qKfrZB-Q\lib\site-packages\django\core\handlers\exception.py", line 47, in inner
    response = get_response(request)
  File "C:\Users\vanis\.virtualenvs\manager_api-qKfrZB-Q\lib\site-packages\django\core\handlers\base.py", line 181, in _get_response
    response = wrapped_callback(request, *callback_args, **callback_kwargs)
  File "C:\Users\vanis\.virtualenvs\manager_api-qKfrZB-Q\lib\site-packages\django\views\decorators\csrf.py", line 54, in wrapped_view
    return view_func(*args, **kwargs)
  File "C:\Users\vanis\.virtualenvs\manager_api-qKfrZB-Q\lib\site-packages\django\views\generic\base.py", line 70, in view
    return self.dispatch(request, *args, **kwargs)
  File "C:\Users\vanis\.virtualenvs\manager_api-qKfrZB-Q\lib\site-packages\rest_framework\views.py", line 509, in dispatch
    response = self.handle_exception(exc)
  File "C:\Users\vanis\.virtualenvs\manager_api-qKfrZB-Q\lib\site-packages\rest_framework\views.py", line 469, in handle_exception
    self.raise_uncaught_exception(exc)
  File "C:\Users\vanis\.virtualenvs\manager_api-qKfrZB-Q\lib\site-packages\rest_framework\views.py", line 480, in raise_uncaught_exception
    raise exc
  File "C:\Users\vanis\.virtualenvs\manager_api-qKfrZB-Q\lib\site-packages\rest_framework\views.py", line 506, in dispatch
    response = handler(request, *args, **kwargs)
  File "C:\Users\vanis\.virtualenvs\manager_api-qKfrZB-Q\lib\site-packages\rest_framework\decorators.py", line 50, in handler
    return func(*args, **kwargs)
  File "C:\Users\vanis\OneDrive\デスクトップ\workspace\03_projects\01_private\manager\manager_api\manager_api_app\views\body_weight_view.py", line 34, in get_weight
    weight_list = BodyWeight.objects.get(users=request.user_name, delete_flag=0)
  File "C:\Users\vanis\.virtualenvs\manager_api-qKfrZB-Q\lib\site-packages\rest_framework\request.py", line 418, in __getattr__
    return self.__getattribute__(attr)
AttributeError: 'Request' object has no attribute 'user_name'
2022-06-04 15:10:02,397 [ERROR] 10232 18112 C:\Users\vanis\.virtualenvs\manager_api-qKfrZB-Q\lib\site-packages\django\core\servers\basehttp.py:157 "POST /manager_api_app/body_weight/ HTTP/1.1" 500 109395
2022-06-04 23:09:05,444 [INFO] 10232 2568 C:\Users\vanis\.virtualenvs\manager_api-qKfrZB-Q\lib\site-packages\django\core\servers\basehttp.py:157 "OPTIONS /manager_api_app/body_weight/ HTTP/1.1" 200 0
2022-06-04 23:09:05,462 [INFO] 10232 24684 C:\Users\vanis\OneDrive\デスクトップ\workspace\03_projects\01_private\manager\manager_api\manager_api_app\views\body_weight_view.py:21 [{'users': 'tetsuya'}, {'users': 'taro'}]
2022-06-04 23:09:05,463 [ERROR] 10232 24684 C:\Users\vanis\OneDrive\デスクトップ\workspace\03_projects\01_private\manager\manager_api\manager_api_app\views\body_weight_view.py:22 log error test!
2022-06-04 23:09:05,464 [INFO] 10232 24684 C:\Users\vanis\.virtualenvs\manager_api-qKfrZB-Q\lib\site-packages\django\core\servers\basehttp.py:157 "GET /manager_api_app/history_user/ HTTP/1.1" 200 89
2022-06-04 23:09:05,846 [ERROR] 10232 17852 C:\Users\vanis\.virtualenvs\manager_api-qKfrZB-Q\lib\site-packages\django\utils\log.py:224 Internal Server Error: /manager_api_app/body_weight/
Traceback (most recent call last):
  File "C:\Users\vanis\.virtualenvs\manager_api-qKfrZB-Q\lib\site-packages\rest_framework\request.py", line 416, in __getattr__
    return getattr(self._request, attr)
AttributeError: 'WSGIRequest' object has no attribute 'user_name'

During handling of the above exception, another exception occurred:

Traceback (most recent call last):
  File "C:\Users\vanis\.virtualenvs\manager_api-qKfrZB-Q\lib\site-packages\django\core\handlers\exception.py", line 47, in inner
    response = get_response(request)
  File "C:\Users\vanis\.virtualenvs\manager_api-qKfrZB-Q\lib\site-packages\django\core\handlers\base.py", line 181, in _get_response
    response = wrapped_callback(request, *callback_args, **callback_kwargs)
  File "C:\Users\vanis\.virtualenvs\manager_api-qKfrZB-Q\lib\site-packages\django\views\decorators\csrf.py", line 54, in wrapped_view
    return view_func(*args, **kwargs)
  File "C:\Users\vanis\.virtualenvs\manager_api-qKfrZB-Q\lib\site-packages\django\views\generic\base.py", line 70, in view
    return self.dispatch(request, *args, **kwargs)
  File "C:\Users\vanis\.virtualenvs\manager_api-qKfrZB-Q\lib\site-packages\rest_framework\views.py", line 509, in dispatch
    response = self.handle_exception(exc)
  File "C:\Users\vanis\.virtualenvs\manager_api-qKfrZB-Q\lib\site-packages\rest_framework\views.py", line 469, in handle_exception
    self.raise_uncaught_exception(exc)
  File "C:\Users\vanis\.virtualenvs\manager_api-qKfrZB-Q\lib\site-packages\rest_framework\views.py", line 480, in raise_uncaught_exception
    raise exc
  File "C:\Users\vanis\.virtualenvs\manager_api-qKfrZB-Q\lib\site-packages\rest_framework\views.py", line 506, in dispatch
    response = handler(request, *args, **kwargs)
  File "C:\Users\vanis\.virtualenvs\manager_api-qKfrZB-Q\lib\site-packages\rest_framework\decorators.py", line 50, in handler
    return func(*args, **kwargs)
  File "C:\Users\vanis\OneDrive\デスクトップ\workspace\03_projects\01_private\manager\manager_api\manager_api_app\views\body_weight_view.py", line 34, in get_weight
    weight_list = BodyWeight.objects.get(users=request.user_name, delete_flag=0)
  File "C:\Users\vanis\.virtualenvs\manager_api-qKfrZB-Q\lib\site-packages\rest_framework\request.py", line 418, in __getattr__
    return self.__getattribute__(attr)
AttributeError: 'Request' object has no attribute 'user_name'
2022-06-04 23:09:05,850 [ERROR] 10232 17852 C:\Users\vanis\.virtualenvs\manager_api-qKfrZB-Q\lib\site-packages\django\core\servers\basehttp.py:157 "POST /manager_api_app/body_weight/ HTTP/1.1" 500 109391
2022-06-04 23:12:50,776 [INFO] 10232 24684 C:\Users\vanis\OneDrive\デスクトップ\workspace\03_projects\01_private\manager\manager_api\manager_api_app\views\body_weight_view.py:21 [{'users': 'tetsuya'}, {'users': 'taro'}]
2022-06-04 23:12:50,777 [ERROR] 10232 24684 C:\Users\vanis\OneDrive\デスクトップ\workspace\03_projects\01_private\manager\manager_api\manager_api_app\views\body_weight_view.py:22 log error test!
2022-06-04 23:12:50,778 [INFO] 10232 24684 C:\Users\vanis\.virtualenvs\manager_api-qKfrZB-Q\lib\site-packages\django\core\servers\basehttp.py:157 "GET /manager_api_app/history_user/ HTTP/1.1" 200 89
2022-06-04 23:12:50,795 [ERROR] 10232 17852 C:\Users\vanis\.virtualenvs\manager_api-qKfrZB-Q\lib\site-packages\django\utils\log.py:224 Internal Server Error: /manager_api_app/body_weight/
Traceback (most recent call last):
  File "C:\Users\vanis\.virtualenvs\manager_api-qKfrZB-Q\lib\site-packages\rest_framework\request.py", line 416, in __getattr__
    return getattr(self._request, attr)
AttributeError: 'WSGIRequest' object has no attribute 'user_name'

During handling of the above exception, another exception occurred:

Traceback (most recent call last):
  File "C:\Users\vanis\.virtualenvs\manager_api-qKfrZB-Q\lib\site-packages\django\core\handlers\exception.py", line 47, in inner
    response = get_response(request)
  File "C:\Users\vanis\.virtualenvs\manager_api-qKfrZB-Q\lib\site-packages\django\core\handlers\base.py", line 181, in _get_response
    response = wrapped_callback(request, *callback_args, **callback_kwargs)
  File "C:\Users\vanis\.virtualenvs\manager_api-qKfrZB-Q\lib\site-packages\django\views\decorators\csrf.py", line 54, in wrapped_view
    return view_func(*args, **kwargs)
  File "C:\Users\vanis\.virtualenvs\manager_api-qKfrZB-Q\lib\site-packages\django\views\generic\base.py", line 70, in view
    return self.dispatch(request, *args, **kwargs)
  File "C:\Users\vanis\.virtualenvs\manager_api-qKfrZB-Q\lib\site-packages\rest_framework\views.py", line 509, in dispatch
    response = self.handle_exception(exc)
  File "C:\Users\vanis\.virtualenvs\manager_api-qKfrZB-Q\lib\site-packages\rest_framework\views.py", line 469, in handle_exception
    self.raise_uncaught_exception(exc)
  File "C:\Users\vanis\.virtualenvs\manager_api-qKfrZB-Q\lib\site-packages\rest_framework\views.py", line 480, in raise_uncaught_exception
    raise exc
  File "C:\Users\vanis\.virtualenvs\manager_api-qKfrZB-Q\lib\site-packages\rest_framework\views.py", line 506, in dispatch
    response = handler(request, *args, **kwargs)
  File "C:\Users\vanis\.virtualenvs\manager_api-qKfrZB-Q\lib\site-packages\rest_framework\decorators.py", line 50, in handler
    return func(*args, **kwargs)
  File "C:\Users\vanis\OneDrive\デスクトップ\workspace\03_projects\01_private\manager\manager_api\manager_api_app\views\body_weight_view.py", line 34, in get_weight
    weight_list = BodyWeight.objects.get(users=request.user_name, delete_flag=0)
  File "C:\Users\vanis\.virtualenvs\manager_api-qKfrZB-Q\lib\site-packages\rest_framework\request.py", line 418, in __getattr__
    return self.__getattribute__(attr)
AttributeError: 'Request' object has no attribute 'user_name'
2022-06-04 23:12:50,799 [ERROR] 10232 17852 C:\Users\vanis\.virtualenvs\manager_api-qKfrZB-Q\lib\site-packages\django\core\servers\basehttp.py:157 "POST /manager_api_app/body_weight/ HTTP/1.1" 500 109391
2022-06-04 23:14:18,762 [INFO] 10232 19640 C:\Users\vanis\.virtualenvs\manager_api-qKfrZB-Q\lib\site-packages\django\utils\autoreload.py:240 C:\Users\vanis\OneDrive\デスクトップ\workspace\03_projects\01_private\manager\manager_api\manager_api_app\common\response_util.py changed, reloading.
2022-06-04 23:14:19,976 [INFO] 16256 21816 C:\Users\vanis\.virtualenvs\manager_api-qKfrZB-Q\lib\site-packages\django\utils\autoreload.py:617 Watching for file changes with StatReloader
2022-06-04 23:15:56,407 [INFO] 16256 21816 C:\Users\vanis\.virtualenvs\manager_api-qKfrZB-Q\lib\site-packages\django\utils\autoreload.py:240 C:\Users\vanis\OneDrive\デスクトップ\workspace\03_projects\01_private\manager\manager_api\manager_api_app\views\body_weight_view.py changed, reloading.
2022-06-04 23:15:57,081 [INFO] 4016 19088 C:\Users\vanis\.virtualenvs\manager_api-qKfrZB-Q\lib\site-packages\django\utils\autoreload.py:617 Watching for file changes with StatReloader
2022-06-04 23:16:00,104 [INFO] 4016 22520 C:\Users\vanis\OneDrive\デスクトップ\workspace\03_projects\01_private\manager\manager_api\manager_api_app\views\body_weight_view.py:21 [{'users': 'tetsuya'}, {'users': 'taro'}]
2022-06-04 23:16:00,104 [ERROR] 4016 22520 C:\Users\vanis\OneDrive\デスクトップ\workspace\03_projects\01_private\manager\manager_api\manager_api_app\views\body_weight_view.py:22 log error test!
2022-06-04 23:16:00,106 [INFO] 4016 22520 C:\Users\vanis\.virtualenvs\manager_api-qKfrZB-Q\lib\site-packages\django\core\servers\basehttp.py:157 "GET /manager_api_app/history_user/ HTTP/1.1" 200 89
2022-06-04 23:16:15,273 [INFO] 23592 4760 C:\Users\vanis\.virtualenvs\manager_api-qKfrZB-Q\lib\site-packages\django\utils\autoreload.py:617 Watching for file changes with StatReloader
2022-06-04 23:17:58,131 [INFO] 23592 20052 C:\Users\vanis\OneDrive\デスクトップ\workspace\03_projects\01_private\manager\manager_api\manager_api_app\views\body_weight_view.py:21 [{'users': 'tetsuya'}, {'users': 'taro'}]
2022-06-04 23:17:58,132 [ERROR] 23592 20052 C:\Users\vanis\OneDrive\デスクトップ\workspace\03_projects\01_private\manager\manager_api\manager_api_app\views\body_weight_view.py:22 log error test!
2022-06-04 23:17:58,133 [INFO] 23592 20052 C:\Users\vanis\.virtualenvs\manager_api-qKfrZB-Q\lib\site-packages\django\core\servers\basehttp.py:157 "GET /manager_api_app/history_user/ HTTP/1.1" 200 89
2022-06-04 23:18:20,147 [INFO] 5192 25560 C:\Users\vanis\.virtualenvs\manager_api-qKfrZB-Q\lib\site-packages\django\utils\autoreload.py:617 Watching for file changes with StatReloader
2022-06-04 23:19:45,388 [ERROR] 5192 7560 C:\Users\vanis\.virtualenvs\manager_api-qKfrZB-Q\lib\site-packages\django\utils\log.py:224 Internal Server Error: /manager_api_app/body_weight/
Traceback (most recent call last):
  File "C:\Users\vanis\.virtualenvs\manager_api-qKfrZB-Q\lib\site-packages\rest_framework\request.py", line 416, in __getattr__
    return getattr(self._request, attr)
AttributeError: 'WSGIRequest' object has no attribute 'user_name'

During handling of the above exception, another exception occurred:

Traceback (most recent call last):
  File "C:\Users\vanis\.virtualenvs\manager_api-qKfrZB-Q\lib\site-packages\django\core\handlers\exception.py", line 47, in inner
    response = get_response(request)
  File "C:\Users\vanis\.virtualenvs\manager_api-qKfrZB-Q\lib\site-packages\django\core\handlers\base.py", line 181, in _get_response
    response = wrapped_callback(request, *callback_args, **callback_kwargs)
  File "C:\Users\vanis\.virtualenvs\manager_api-qKfrZB-Q\lib\site-packages\django\views\decorators\csrf.py", line 54, in wrapped_view
    return view_func(*args, **kwargs)
  File "C:\Users\vanis\.virtualenvs\manager_api-qKfrZB-Q\lib\site-packages\django\views\generic\base.py", line 70, in view
    return self.dispatch(request, *args, **kwargs)
  File "C:\Users\vanis\.virtualenvs\manager_api-qKfrZB-Q\lib\site-packages\rest_framework\views.py", line 509, in dispatch
    response = self.handle_exception(exc)
  File "C:\Users\vanis\.virtualenvs\manager_api-qKfrZB-Q\lib\site-packages\rest_framework\views.py", line 469, in handle_exception
    self.raise_uncaught_exception(exc)
  File "C:\Users\vanis\.virtualenvs\manager_api-qKfrZB-Q\lib\site-packages\rest_framework\views.py", line 480, in raise_uncaught_exception
    raise exc
  File "C:\Users\vanis\.virtualenvs\manager_api-qKfrZB-Q\lib\site-packages\rest_framework\views.py", line 506, in dispatch
    response = handler(request, *args, **kwargs)
  File "C:\Users\vanis\.virtualenvs\manager_api-qKfrZB-Q\lib\site-packages\rest_framework\decorators.py", line 50, in handler
    return func(*args, **kwargs)
  File "C:\Users\vanis\OneDrive\デスクトップ\workspace\03_projects\01_private\manager\manager_api\manager_api_app\views\body_weight_view.py", line 34, in get_weight
    weight_list = BodyWeight.objects.get(users=request.user_name, delete_flag=0)
  File "C:\Users\vanis\.virtualenvs\manager_api-qKfrZB-Q\lib\site-packages\rest_framework\request.py", line 418, in __getattr__
    return self.__getattribute__(attr)
AttributeError: 'Request' object has no attribute 'user_name'
2022-06-04 23:19:45,394 [ERROR] 5192 7560 C:\Users\vanis\.virtualenvs\manager_api-qKfrZB-Q\lib\site-packages\django\core\servers\basehttp.py:157 "POST /manager_api_app/body_weight/ HTTP/1.1" 500 109407
2022-06-04 23:19:50,339 [ERROR] 5192 7560 C:\Users\vanis\.virtualenvs\manager_api-qKfrZB-Q\lib\site-packages\django\utils\log.py:224 Internal Server Error: /manager_api_app/body_weight/
Traceback (most recent call last):
  File "C:\Users\vanis\.virtualenvs\manager_api-qKfrZB-Q\lib\site-packages\rest_framework\request.py", line 416, in __getattr__
    return getattr(self._request, attr)
AttributeError: 'WSGIRequest' object has no attribute 'user_name'

During handling of the above exception, another exception occurred:

Traceback (most recent call last):
  File "C:\Users\vanis\.virtualenvs\manager_api-qKfrZB-Q\lib\site-packages\django\core\handlers\exception.py", line 47, in inner
    response = get_response(request)
  File "C:\Users\vanis\.virtualenvs\manager_api-qKfrZB-Q\lib\site-packages\django\core\handlers\base.py", line 181, in _get_response
    response = wrapped_callback(request, *callback_args, **callback_kwargs)
  File "C:\Users\vanis\.virtualenvs\manager_api-qKfrZB-Q\lib\site-packages\django\views\decorators\csrf.py", line 54, in wrapped_view
    return view_func(*args, **kwargs)
  File "C:\Users\vanis\.virtualenvs\manager_api-qKfrZB-Q\lib\site-packages\django\views\generic\base.py", line 70, in view
    return self.dispatch(request, *args, **kwargs)
  File "C:\Users\vanis\.virtualenvs\manager_api-qKfrZB-Q\lib\site-packages\rest_framework\views.py", line 509, in dispatch
    response = self.handle_exception(exc)
  File "C:\Users\vanis\.virtualenvs\manager_api-qKfrZB-Q\lib\site-packages\rest_framework\views.py", line 469, in handle_exception
    self.raise_uncaught_exception(exc)
  File "C:\Users\vanis\.virtualenvs\manager_api-qKfrZB-Q\lib\site-packages\rest_framework\views.py", line 480, in raise_uncaught_exception
    raise exc
  File "C:\Users\vanis\.virtualenvs\manager_api-qKfrZB-Q\lib\site-packages\rest_framework\views.py", line 506, in dispatch
    response = handler(request, *args, **kwargs)
  File "C:\Users\vanis\.virtualenvs\manager_api-qKfrZB-Q\lib\site-packages\rest_framework\decorators.py", line 50, in handler
    return func(*args, **kwargs)
  File "C:\Users\vanis\OneDrive\デスクトップ\workspace\03_projects\01_private\manager\manager_api\manager_api_app\views\body_weight_view.py", line 34, in get_weight
    weight_list = BodyWeight.objects.get(users=request.user_name, delete_flag=0)
  File "C:\Users\vanis\.virtualenvs\manager_api-qKfrZB-Q\lib\site-packages\rest_framework\request.py", line 418, in __getattr__
    return self.__getattribute__(attr)
AttributeError: 'Request' object has no attribute 'user_name'
2022-06-04 23:19:50,343 [ERROR] 5192 7560 C:\Users\vanis\.virtualenvs\manager_api-qKfrZB-Q\lib\site-packages\django\core\servers\basehttp.py:157 "POST /manager_api_app/body_weight/ HTTP/1.1" 500 109407
2022-06-04 23:20:46,026 [INFO] 5192 25560 C:\Users\vanis\.virtualenvs\manager_api-qKfrZB-Q\lib\site-packages\django\utils\autoreload.py:240 C:\Users\vanis\OneDrive\デスクトップ\workspace\03_projects\01_private\manager\manager_api\manager_api_app\views\body_weight_view.py changed, reloading.
2022-06-04 23:20:46,694 [INFO] 620 10860 C:\Users\vanis\.virtualenvs\manager_api-qKfrZB-Q\lib\site-packages\django\utils\autoreload.py:617 Watching for file changes with StatReloader
2022-06-04 23:20:51,788 [ERROR] 620 20024 C:\Users\vanis\.virtualenvs\manager_api-qKfrZB-Q\lib\site-packages\django\utils\log.py:224 Internal Server Error: /manager_api_app/body_weight/
Traceback (most recent call last):
  File "C:\Users\vanis\.virtualenvs\manager_api-qKfrZB-Q\lib\site-packages\rest_framework\request.py", line 416, in __getattr__
    return getattr(self._request, attr)
AttributeError: 'WSGIRequest' object has no attribute 'user_name'

During handling of the above exception, another exception occurred:

Traceback (most recent call last):
  File "C:\Users\vanis\.virtualenvs\manager_api-qKfrZB-Q\lib\site-packages\django\core\handlers\exception.py", line 47, in inner
    response = get_response(request)
  File "C:\Users\vanis\.virtualenvs\manager_api-qKfrZB-Q\lib\site-packages\django\core\handlers\base.py", line 181, in _get_response
    response = wrapped_callback(request, *callback_args, **callback_kwargs)
  File "C:\Users\vanis\.virtualenvs\manager_api-qKfrZB-Q\lib\site-packages\django\views\decorators\csrf.py", line 54, in wrapped_view
    return view_func(*args, **kwargs)
  File "C:\Users\vanis\.virtualenvs\manager_api-qKfrZB-Q\lib\site-packages\django\views\generic\base.py", line 70, in view
    return self.dispatch(request, *args, **kwargs)
  File "C:\Users\vanis\.virtualenvs\manager_api-qKfrZB-Q\lib\site-packages\rest_framework\views.py", line 509, in dispatch
    response = self.handle_exception(exc)
  File "C:\Users\vanis\.virtualenvs\manager_api-qKfrZB-Q\lib\site-packages\rest_framework\views.py", line 469, in handle_exception
    self.raise_uncaught_exception(exc)
  File "C:\Users\vanis\.virtualenvs\manager_api-qKfrZB-Q\lib\site-packages\rest_framework\views.py", line 480, in raise_uncaught_exception
    raise exc
  File "C:\Users\vanis\.virtualenvs\manager_api-qKfrZB-Q\lib\site-packages\rest_framework\views.py", line 506, in dispatch
    response = handler(request, *args, **kwargs)
  File "C:\Users\vanis\.virtualenvs\manager_api-qKfrZB-Q\lib\site-packages\rest_framework\decorators.py", line 50, in handler
    return func(*args, **kwargs)
  File "C:\Users\vanis\OneDrive\デスクトップ\workspace\03_projects\01_private\manager\manager_api\manager_api_app\views\body_weight_view.py", line 33, in get_weight
    weight_list = BodyWeight.objects.get(users=request.user_name, delete_flag=0)
  File "C:\Users\vanis\.virtualenvs\manager_api-qKfrZB-Q\lib\site-packages\rest_framework\request.py", line 418, in __getattr__
    return self.__getattribute__(attr)
AttributeError: 'Request' object has no attribute 'user_name'
2022-06-04 23:20:51,792 [ERROR] 620 20024 C:\Users\vanis\.virtualenvs\manager_api-qKfrZB-Q\lib\site-packages\django\core\servers\basehttp.py:157 "POST /manager_api_app/body_weight/ HTTP/1.1" 500 109407
2022-06-04 23:23:48,549 [INFO] 620 10860 C:\Users\vanis\.virtualenvs\manager_api-qKfrZB-Q\lib\site-packages\django\utils\autoreload.py:240 C:\Users\vanis\OneDrive\デスクトップ\workspace\03_projects\01_private\manager\manager_api\manager_api_app\views\body_weight_view.py changed, reloading.
2022-06-04 23:23:49,252 [INFO] 11208 21900 C:\Users\vanis\.virtualenvs\manager_api-qKfrZB-Q\lib\site-packages\django\utils\autoreload.py:617 Watching for file changes with StatReloader
2022-06-04 23:23:57,154 [INFO] 11208 12784 C:\Users\vanis\OneDrive\デスクトップ\workspace\03_projects\01_private\manager\manager_api\manager_api_app\views\body_weight_view.py:21 result_data:[{'users': 'tetsuya'}, {'users': 'taro'}]
2022-06-04 23:23:57,156 [INFO] 11208 12784 C:\Users\vanis\.virtualenvs\manager_api-qKfrZB-Q\lib\site-packages\django\core\servers\basehttp.py:157 "GET /manager_api_app/history_user/ HTTP/1.1" 200 89
2022-06-04 23:23:59,159 [ERROR] 11208 24372 C:\Users\vanis\.virtualenvs\manager_api-qKfrZB-Q\lib\site-packages\django\utils\log.py:224 Internal Server Error: /manager_api_app/body_weight/
Traceback (most recent call last):
  File "C:\Users\vanis\.virtualenvs\manager_api-qKfrZB-Q\lib\site-packages\rest_framework\request.py", line 416, in __getattr__
    return getattr(self._request, attr)
AttributeError: 'WSGIRequest' object has no attribute 'user_name'

During handling of the above exception, another exception occurred:

Traceback (most recent call last):
  File "C:\Users\vanis\.virtualenvs\manager_api-qKfrZB-Q\lib\site-packages\django\core\handlers\exception.py", line 47, in inner
    response = get_response(request)
  File "C:\Users\vanis\.virtualenvs\manager_api-qKfrZB-Q\lib\site-packages\django\core\handlers\base.py", line 181, in _get_response
    response = wrapped_callback(request, *callback_args, **callback_kwargs)
  File "C:\Users\vanis\.virtualenvs\manager_api-qKfrZB-Q\lib\site-packages\django\views\decorators\csrf.py", line 54, in wrapped_view
    return view_func(*args, **kwargs)
  File "C:\Users\vanis\.virtualenvs\manager_api-qKfrZB-Q\lib\site-packages\django\views\generic\base.py", line 70, in view
    return self.dispatch(request, *args, **kwargs)
  File "C:\Users\vanis\.virtualenvs\manager_api-qKfrZB-Q\lib\site-packages\rest_framework\views.py", line 509, in dispatch
    response = self.handle_exception(exc)
  File "C:\Users\vanis\.virtualenvs\manager_api-qKfrZB-Q\lib\site-packages\rest_framework\views.py", line 469, in handle_exception
    self.raise_uncaught_exception(exc)
  File "C:\Users\vanis\.virtualenvs\manager_api-qKfrZB-Q\lib\site-packages\rest_framework\views.py", line 480, in raise_uncaught_exception
    raise exc
  File "C:\Users\vanis\.virtualenvs\manager_api-qKfrZB-Q\lib\site-packages\rest_framework\views.py", line 506, in dispatch
    response = handler(request, *args, **kwargs)
  File "C:\Users\vanis\.virtualenvs\manager_api-qKfrZB-Q\lib\site-packages\rest_framework\decorators.py", line 50, in handler
    return func(*args, **kwargs)
  File "C:\Users\vanis\OneDrive\デスクトップ\workspace\03_projects\01_private\manager\manager_api\manager_api_app\views\body_weight_view.py", line 33, in get_weight
    weight_list = BodyWeight.objects.get(users=self.user_name, delete_flag=0)
  File "C:\Users\vanis\.virtualenvs\manager_api-qKfrZB-Q\lib\site-packages\rest_framework\request.py", line 418, in __getattr__
    return self.__getattribute__(attr)
AttributeError: 'Request' object has no attribute 'user_name'
2022-06-04 23:23:59,164 [ERROR] 11208 24372 C:\Users\vanis\.virtualenvs\manager_api-qKfrZB-Q\lib\site-packages\django\core\servers\basehttp.py:157 "POST /manager_api_app/body_weight/ HTTP/1.1" 500 109395
2022-06-04 23:25:45,859 [INFO] 11208 21900 C:\Users\vanis\.virtualenvs\manager_api-qKfrZB-Q\lib\site-packages\django\utils\autoreload.py:240 C:\Users\vanis\OneDrive\デスクトップ\workspace\03_projects\01_private\manager\manager_api\manager_api_app\views\body_weight_view.py changed, reloading.
2022-06-04 23:25:46,611 [INFO] 4176 7344 C:\Users\vanis\.virtualenvs\manager_api-qKfrZB-Q\lib\site-packages\django\utils\autoreload.py:617 Watching for file changes with StatReloader
2022-06-04 23:27:47,305 [INFO] 4176 7344 C:\Users\vanis\.virtualenvs\manager_api-qKfrZB-Q\lib\site-packages\django\utils\autoreload.py:240 C:\Users\vanis\OneDrive\デスクトップ\workspace\03_projects\01_private\manager\manager_api\manager_api_app\views\body_weight_view.py changed, reloading.
2022-06-04 23:27:48,003 [INFO] 9268 13792 C:\Users\vanis\.virtualenvs\manager_api-qKfrZB-Q\lib\site-packages\django\utils\autoreload.py:617 Watching for file changes with StatReloader
2022-06-04 23:27:52,326 [INFO] 9268 24320 C:\Users\vanis\OneDrive\デスクトップ\workspace\03_projects\01_private\manager\manager_api\manager_api_app\views\body_weight_view.py:21 result_data:[{'users': 'tetsuya'}, {'users': 'taro'}]
2022-06-04 23:27:52,327 [INFO] 9268 24320 C:\Users\vanis\.virtualenvs\manager_api-qKfrZB-Q\lib\site-packages\django\core\servers\basehttp.py:157 "GET /manager_api_app/history_user/ HTTP/1.1" 200 89
2022-06-04 23:27:53,616 [ERROR] 9268 24412 C:\Users\vanis\.virtualenvs\manager_api-qKfrZB-Q\lib\site-packages\django\utils\log.py:224 Internal Server Error: /manager_api_app/body_weight/
Traceback (most recent call last):
  File "C:\Users\vanis\.virtualenvs\manager_api-qKfrZB-Q\lib\site-packages\django\core\handlers\exception.py", line 47, in inner
    response = get_response(request)
  File "C:\Users\vanis\.virtualenvs\manager_api-qKfrZB-Q\lib\site-packages\django\core\handlers\base.py", line 181, in _get_response
    response = wrapped_callback(request, *callback_args, **callback_kwargs)
  File "C:\Users\vanis\.virtualenvs\manager_api-qKfrZB-Q\lib\site-packages\django\views\decorators\csrf.py", line 54, in wrapped_view
    return view_func(*args, **kwargs)
  File "C:\Users\vanis\.virtualenvs\manager_api-qKfrZB-Q\lib\site-packages\django\views\generic\base.py", line 70, in view
    return self.dispatch(request, *args, **kwargs)
  File "C:\Users\vanis\.virtualenvs\manager_api-qKfrZB-Q\lib\site-packages\rest_framework\views.py", line 509, in dispatch
    response = self.handle_exception(exc)
  File "C:\Users\vanis\.virtualenvs\manager_api-qKfrZB-Q\lib\site-packages\rest_framework\views.py", line 469, in handle_exception
    self.raise_uncaught_exception(exc)
  File "C:\Users\vanis\.virtualenvs\manager_api-qKfrZB-Q\lib\site-packages\rest_framework\views.py", line 480, in raise_uncaught_exception
    raise exc
  File "C:\Users\vanis\.virtualenvs\manager_api-qKfrZB-Q\lib\site-packages\rest_framework\views.py", line 506, in dispatch
    response = handler(request, *args, **kwargs)
  File "C:\Users\vanis\.virtualenvs\manager_api-qKfrZB-Q\lib\site-packages\rest_framework\decorators.py", line 50, in handler
    return func(*args, **kwargs)
TypeError: BodyWeightView.get_weight() missing 1 required positional argument: 'request'
2022-06-04 23:27:53,626 [ERROR] 9268 24412 C:\Users\vanis\.virtualenvs\manager_api-qKfrZB-Q\lib\site-packages\django\core\servers\basehttp.py:157 "POST /manager_api_app/body_weight/ HTTP/1.1" 500 97484
2022-06-04 23:28:16,646 [INFO] 9268 13792 C:\Users\vanis\.virtualenvs\manager_api-qKfrZB-Q\lib\site-packages\django\utils\autoreload.py:240 C:\Users\vanis\OneDrive\デスクトップ\workspace\03_projects\01_private\manager\manager_api\manager_api_app\views\body_weight_view.py changed, reloading.
2022-06-04 23:28:17,561 [INFO] 9208 14876 C:\Users\vanis\.virtualenvs\manager_api-qKfrZB-Q\lib\site-packages\django\utils\autoreload.py:617 Watching for file changes with StatReloader
2022-06-04 23:28:17,854 [INFO] 9208 25576 C:\Users\vanis\OneDrive\デスクトップ\workspace\03_projects\01_private\manager\manager_api\manager_api_app\views\body_weight_view.py:21 result_data:[{'users': 'tetsuya'}, {'users': 'taro'}]
2022-06-04 23:28:17,856 [INFO] 9208 25576 C:\Users\vanis\.virtualenvs\manager_api-qKfrZB-Q\lib\site-packages\django\core\servers\basehttp.py:157 "GET /manager_api_app/history_user/ HTTP/1.1" 200 89
2022-06-04 23:28:18,745 [ERROR] 9208 8576 C:\Users\vanis\.virtualenvs\manager_api-qKfrZB-Q\lib\site-packages\django\utils\log.py:224 Internal Server Error: /manager_api_app/body_weight/
Traceback (most recent call last):
  File "C:\Users\vanis\.virtualenvs\manager_api-qKfrZB-Q\lib\site-packages\django\core\handlers\exception.py", line 47, in inner
    response = get_response(request)
  File "C:\Users\vanis\.virtualenvs\manager_api-qKfrZB-Q\lib\site-packages\django\core\handlers\base.py", line 181, in _get_response
    response = wrapped_callback(request, *callback_args, **callback_kwargs)
  File "C:\Users\vanis\.virtualenvs\manager_api-qKfrZB-Q\lib\site-packages\django\views\decorators\csrf.py", line 54, in wrapped_view
    return view_func(*args, **kwargs)
  File "C:\Users\vanis\.virtualenvs\manager_api-qKfrZB-Q\lib\site-packages\django\views\generic\base.py", line 70, in view
    return self.dispatch(request, *args, **kwargs)
  File "C:\Users\vanis\.virtualenvs\manager_api-qKfrZB-Q\lib\site-packages\rest_framework\views.py", line 509, in dispatch
    response = self.handle_exception(exc)
  File "C:\Users\vanis\.virtualenvs\manager_api-qKfrZB-Q\lib\site-packages\rest_framework\views.py", line 469, in handle_exception
    self.raise_uncaught_exception(exc)
  File "C:\Users\vanis\.virtualenvs\manager_api-qKfrZB-Q\lib\site-packages\rest_framework\views.py", line 480, in raise_uncaught_exception
    raise exc
  File "C:\Users\vanis\.virtualenvs\manager_api-qKfrZB-Q\lib\site-packages\rest_framework\views.py", line 506, in dispatch
    response = handler(request, *args, **kwargs)
  File "C:\Users\vanis\.virtualenvs\manager_api-qKfrZB-Q\lib\site-packages\rest_framework\decorators.py", line 50, in handler
    return func(*args, **kwargs)
TypeError: BodyWeightView.get_weight() missing 1 required positional argument: 'request'
2022-06-04 23:28:18,757 [ERROR] 9208 8576 C:\Users\vanis\.virtualenvs\manager_api-qKfrZB-Q\lib\site-packages\django\core\servers\basehttp.py:157 "POST /manager_api_app/body_weight/ HTTP/1.1" 500 97484
2022-06-04 23:28:25,136 [INFO] 9208 14876 C:\Users\vanis\.virtualenvs\manager_api-qKfrZB-Q\lib\site-packages\django\utils\autoreload.py:240 C:\Users\vanis\OneDrive\デスクトップ\workspace\03_projects\01_private\manager\manager_api\manager_api_app\views\body_weight_view.py changed, reloading.
2022-06-04 23:28:26,176 [INFO] 14172 20860 C:\Users\vanis\.virtualenvs\manager_api-qKfrZB-Q\lib\site-packages\django\utils\autoreload.py:617 Watching for file changes with StatReloader
2022-06-04 23:28:26,333 [INFO] 14172 2824 C:\Users\vanis\OneDrive\デスクトップ\workspace\03_projects\01_private\manager\manager_api\manager_api_app\views\body_weight_view.py:21 result_data:[{'users': 'tetsuya'}, {'users': 'taro'}]
2022-06-04 23:28:26,335 [INFO] 14172 2824 C:\Users\vanis\.virtualenvs\manager_api-qKfrZB-Q\lib\site-packages\django\core\servers\basehttp.py:157 "GET /manager_api_app/history_user/ HTTP/1.1" 200 89
2022-06-04 23:28:28,113 [ERROR] 14172 5556 C:\Users\vanis\.virtualenvs\manager_api-qKfrZB-Q\lib\site-packages\django\utils\log.py:224 Internal Server Error: /manager_api_app/body_weight/
Traceback (most recent call last):
  File "C:\Users\vanis\.virtualenvs\manager_api-qKfrZB-Q\lib\site-packages\django\core\handlers\exception.py", line 47, in inner
    response = get_response(request)
  File "C:\Users\vanis\.virtualenvs\manager_api-qKfrZB-Q\lib\site-packages\django\core\handlers\base.py", line 181, in _get_response
    response = wrapped_callback(request, *callback_args, **callback_kwargs)
  File "C:\Users\vanis\.virtualenvs\manager_api-qKfrZB-Q\lib\site-packages\django\views\decorators\csrf.py", line 54, in wrapped_view
    return view_func(*args, **kwargs)
  File "C:\Users\vanis\.virtualenvs\manager_api-qKfrZB-Q\lib\site-packages\django\views\generic\base.py", line 70, in view
    return self.dispatch(request, *args, **kwargs)
  File "C:\Users\vanis\.virtualenvs\manager_api-qKfrZB-Q\lib\site-packages\rest_framework\views.py", line 509, in dispatch
    response = self.handle_exception(exc)
  File "C:\Users\vanis\.virtualenvs\manager_api-qKfrZB-Q\lib\site-packages\rest_framework\views.py", line 469, in handle_exception
    self.raise_uncaught_exception(exc)
  File "C:\Users\vanis\.virtualenvs\manager_api-qKfrZB-Q\lib\site-packages\rest_framework\views.py", line 480, in raise_uncaught_exception
    raise exc
  File "C:\Users\vanis\.virtualenvs\manager_api-qKfrZB-Q\lib\site-packages\rest_framework\views.py", line 506, in dispatch
    response = handler(request, *args, **kwargs)
  File "C:\Users\vanis\.virtualenvs\manager_api-qKfrZB-Q\lib\site-packages\rest_framework\decorators.py", line 50, in handler
    return func(*args, **kwargs)
  File "C:\Users\vanis\OneDrive\デスクトップ\workspace\03_projects\01_private\manager\manager_api\manager_api_app\views\body_weight_view.py", line 33, in get_weight
    weight_list = BodyWeight.objects.get(users=request.GET.get(user_data), delete_flag=0)
NameError: name 'user_data' is not defined
2022-06-04 23:28:28,117 [ERROR] 14172 5556 C:\Users\vanis\.virtualenvs\manager_api-qKfrZB-Q\lib\site-packages\django\core\servers\basehttp.py:157 "POST /manager_api_app/body_weight/ HTTP/1.1" 500 101175
2022-06-04 23:28:42,176 [INFO] 14172 20860 C:\Users\vanis\.virtualenvs\manager_api-qKfrZB-Q\lib\site-packages\django\utils\autoreload.py:240 C:\Users\vanis\OneDrive\デスクトップ\workspace\03_projects\01_private\manager\manager_api\manager_api_app\views\body_weight_view.py changed, reloading.
2022-06-04 23:28:43,021 [INFO] 23788 14380 C:\Users\vanis\.virtualenvs\manager_api-qKfrZB-Q\lib\site-packages\django\utils\autoreload.py:617 Watching for file changes with StatReloader
2022-06-04 23:28:43,386 [INFO] 23788 14508 C:\Users\vanis\OneDrive\デスクトップ\workspace\03_projects\01_private\manager\manager_api\manager_api_app\views\body_weight_view.py:21 result_data:[{'users': 'tetsuya'}, {'users': 'taro'}]
2022-06-04 23:28:43,387 [INFO] 23788 14508 C:\Users\vanis\.virtualenvs\manager_api-qKfrZB-Q\lib\site-packages\django\core\servers\basehttp.py:157 "GET /manager_api_app/history_user/ HTTP/1.1" 200 89
2022-06-04 23:28:45,854 [ERROR] 23788 24184 C:\Users\vanis\.virtualenvs\manager_api-qKfrZB-Q\lib\site-packages\django\utils\log.py:224 Internal Server Error: /manager_api_app/body_weight/
Traceback (most recent call last):
  File "C:\Users\vanis\.virtualenvs\manager_api-qKfrZB-Q\lib\site-packages\django\core\handlers\exception.py", line 47, in inner
    response = get_response(request)
  File "C:\Users\vanis\.virtualenvs\manager_api-qKfrZB-Q\lib\site-packages\django\core\handlers\base.py", line 181, in _get_response
    response = wrapped_callback(request, *callback_args, **callback_kwargs)
  File "C:\Users\vanis\.virtualenvs\manager_api-qKfrZB-Q\lib\site-packages\django\views\decorators\csrf.py", line 54, in wrapped_view
    return view_func(*args, **kwargs)
  File "C:\Users\vanis\.virtualenvs\manager_api-qKfrZB-Q\lib\site-packages\django\views\generic\base.py", line 70, in view
    return self.dispatch(request, *args, **kwargs)
  File "C:\Users\vanis\.virtualenvs\manager_api-qKfrZB-Q\lib\site-packages\rest_framework\views.py", line 509, in dispatch
    response = self.handle_exception(exc)
  File "C:\Users\vanis\.virtualenvs\manager_api-qKfrZB-Q\lib\site-packages\rest_framework\views.py", line 469, in handle_exception
    self.raise_uncaught_exception(exc)
  File "C:\Users\vanis\.virtualenvs\manager_api-qKfrZB-Q\lib\site-packages\rest_framework\views.py", line 480, in raise_uncaught_exception
    raise exc
  File "C:\Users\vanis\.virtualenvs\manager_api-qKfrZB-Q\lib\site-packages\rest_framework\views.py", line 506, in dispatch
    response = handler(request, *args, **kwargs)
  File "C:\Users\vanis\.virtualenvs\manager_api-qKfrZB-Q\lib\site-packages\rest_framework\decorators.py", line 50, in handler
    return func(*args, **kwargs)
  File "C:\Users\vanis\OneDrive\デスクトップ\workspace\03_projects\01_private\manager\manager_api\manager_api_app\views\body_weight_view.py", line 33, in get_weight
    weight_list = BodyWeight.objects.get(users=request.GET.get(user_name), delete_flag=0)
NameError: name 'user_name' is not defined
2022-06-04 23:28:45,865 [ERROR] 23788 24184 C:\Users\vanis\.virtualenvs\manager_api-qKfrZB-Q\lib\site-packages\django\core\servers\basehttp.py:157 "POST /manager_api_app/body_weight/ HTTP/1.1" 500 101175
2022-06-04 23:29:27,029 [INFO] 23788 14380 C:\Users\vanis\.virtualenvs\manager_api-qKfrZB-Q\lib\site-packages\django\utils\autoreload.py:240 C:\Users\vanis\OneDrive\デスクトップ\workspace\03_projects\01_private\manager\manager_api\manager_api_app\views\body_weight_view.py changed, reloading.
2022-06-04 23:29:27,878 [INFO] 10112 19712 C:\Users\vanis\.virtualenvs\manager_api-qKfrZB-Q\lib\site-packages\django\utils\autoreload.py:617 Watching for file changes with StatReloader
2022-06-04 23:29:29,245 [INFO] 10112 8124 C:\Users\vanis\OneDrive\デスクトップ\workspace\03_projects\01_private\manager\manager_api\manager_api_app\views\body_weight_view.py:21 result_data:[{'users': 'tetsuya'}, {'users': 'taro'}]
2022-06-04 23:29:29,246 [INFO] 10112 8124 C:\Users\vanis\.virtualenvs\manager_api-qKfrZB-Q\lib\site-packages\django\core\servers\basehttp.py:157 "GET /manager_api_app/history_user/ HTTP/1.1" 200 89
2022-06-04 23:29:32,579 [ERROR] 10112 23176 C:\Users\vanis\.virtualenvs\manager_api-qKfrZB-Q\lib\site-packages\django\utils\log.py:224 Internal Server Error: /manager_api_app/body_weight/
Traceback (most recent call last):
  File "C:\Users\vanis\.virtualenvs\manager_api-qKfrZB-Q\lib\site-packages\django\core\handlers\exception.py", line 47, in inner
    response = get_response(request)
  File "C:\Users\vanis\.virtualenvs\manager_api-qKfrZB-Q\lib\site-packages\django\core\handlers\base.py", line 181, in _get_response
    response = wrapped_callback(request, *callback_args, **callback_kwargs)
  File "C:\Users\vanis\.virtualenvs\manager_api-qKfrZB-Q\lib\site-packages\django\views\decorators\csrf.py", line 54, in wrapped_view
    return view_func(*args, **kwargs)
  File "C:\Users\vanis\.virtualenvs\manager_api-qKfrZB-Q\lib\site-packages\django\views\generic\base.py", line 70, in view
    return self.dispatch(request, *args, **kwargs)
  File "C:\Users\vanis\.virtualenvs\manager_api-qKfrZB-Q\lib\site-packages\rest_framework\views.py", line 509, in dispatch
    response = self.handle_exception(exc)
  File "C:\Users\vanis\.virtualenvs\manager_api-qKfrZB-Q\lib\site-packages\rest_framework\views.py", line 469, in handle_exception
    self.raise_uncaught_exception(exc)
  File "C:\Users\vanis\.virtualenvs\manager_api-qKfrZB-Q\lib\site-packages\rest_framework\views.py", line 480, in raise_uncaught_exception
    raise exc
  File "C:\Users\vanis\.virtualenvs\manager_api-qKfrZB-Q\lib\site-packages\rest_framework\views.py", line 506, in dispatch
    response = handler(request, *args, **kwargs)
  File "C:\Users\vanis\.virtualenvs\manager_api-qKfrZB-Q\lib\site-packages\rest_framework\decorators.py", line 50, in handler
    return func(*args, **kwargs)
  File "C:\Users\vanis\OneDrive\デスクトップ\workspace\03_projects\01_private\manager\manager_api\manager_api_app\views\body_weight_view.py", line 34, in get_weight
    logger.info(f"request.GET:{request.GET}")
UnboundLocalError: local variable 'logger' referenced before assignment
2022-06-04 23:29:32,584 [ERROR] 10112 23176 C:\Users\vanis\.virtualenvs\manager_api-qKfrZB-Q\lib\site-packages\django\core\servers\basehttp.py:157 "POST /manager_api_app/body_weight/ HTTP/1.1" 500 101389
2022-06-04 23:30:00,653 [INFO] 10112 19712 C:\Users\vanis\.virtualenvs\manager_api-qKfrZB-Q\lib\site-packages\django\utils\autoreload.py:240 C:\Users\vanis\OneDrive\デスクトップ\workspace\03_projects\01_private\manager\manager_api\manager_api_app\views\body_weight_view.py changed, reloading.
2022-06-04 23:30:01,450 [INFO] 21376 2740 C:\Users\vanis\.virtualenvs\manager_api-qKfrZB-Q\lib\site-packages\django\utils\autoreload.py:617 Watching for file changes with StatReloader
2022-06-04 23:30:01,633 [INFO] 21376 7348 C:\Users\vanis\OneDrive\デスクトップ\workspace\03_projects\01_private\manager\manager_api\manager_api_app\views\body_weight_view.py:21 result_data:[{'users': 'tetsuya'}, {'users': 'taro'}]
2022-06-04 23:30:01,634 [INFO] 21376 7348 C:\Users\vanis\.virtualenvs\manager_api-qKfrZB-Q\lib\site-packages\django\core\servers\basehttp.py:157 "GET /manager_api_app/history_user/ HTTP/1.1" 200 89
2022-06-04 23:30:02,211 [INFO] 21376 15480 C:\Users\vanis\OneDrive\デスクトップ\workspace\03_projects\01_private\manager\manager_api\manager_api_app\views\body_weight_view.py:35 request.GET:<QueryDict: {}>
2022-06-04 23:30:02,280 [ERROR] 21376 15480 C:\Users\vanis\.virtualenvs\manager_api-qKfrZB-Q\lib\site-packages\django\utils\log.py:224 Internal Server Error: /manager_api_app/body_weight/
Traceback (most recent call last):
  File "C:\Users\vanis\.virtualenvs\manager_api-qKfrZB-Q\lib\site-packages\django\core\handlers\exception.py", line 47, in inner
    response = get_response(request)
  File "C:\Users\vanis\.virtualenvs\manager_api-qKfrZB-Q\lib\site-packages\django\core\handlers\base.py", line 181, in _get_response
    response = wrapped_callback(request, *callback_args, **callback_kwargs)
  File "C:\Users\vanis\.virtualenvs\manager_api-qKfrZB-Q\lib\site-packages\django\views\decorators\csrf.py", line 54, in wrapped_view
    return view_func(*args, **kwargs)
  File "C:\Users\vanis\.virtualenvs\manager_api-qKfrZB-Q\lib\site-packages\django\views\generic\base.py", line 70, in view
    return self.dispatch(request, *args, **kwargs)
  File "C:\Users\vanis\.virtualenvs\manager_api-qKfrZB-Q\lib\site-packages\rest_framework\views.py", line 509, in dispatch
    response = self.handle_exception(exc)
  File "C:\Users\vanis\.virtualenvs\manager_api-qKfrZB-Q\lib\site-packages\rest_framework\views.py", line 469, in handle_exception
    self.raise_uncaught_exception(exc)
  File "C:\Users\vanis\.virtualenvs\manager_api-qKfrZB-Q\lib\site-packages\rest_framework\views.py", line 480, in raise_uncaught_exception
    raise exc
  File "C:\Users\vanis\.virtualenvs\manager_api-qKfrZB-Q\lib\site-packages\rest_framework\views.py", line 506, in dispatch
    response = handler(request, *args, **kwargs)
  File "C:\Users\vanis\.virtualenvs\manager_api-qKfrZB-Q\lib\site-packages\rest_framework\decorators.py", line 50, in handler
    return func(*args, **kwargs)
  File "C:\Users\vanis\OneDrive\デスクトップ\workspace\03_projects\01_private\manager\manager_api\manager_api_app\views\body_weight_view.py", line 36, in get_weight
    logger.info(f"weight_list:{weight_list}")
NameError: name 'weight_list' is not defined
2022-06-04 23:30:02,289 [ERROR] 21376 15480 C:\Users\vanis\.virtualenvs\manager_api-qKfrZB-Q\lib\site-packages\django\core\servers\basehttp.py:157 "POST /manager_api_app/body_weight/ HTTP/1.1" 500 101458
2022-06-04 23:30:15,428 [INFO] 21376 2740 C:\Users\vanis\.virtualenvs\manager_api-qKfrZB-Q\lib\site-packages\django\utils\autoreload.py:240 C:\Users\vanis\OneDrive\デスクトップ\workspace\03_projects\01_private\manager\manager_api\manager_api_app\views\body_weight_view.py changed, reloading.
2022-06-04 23:30:16,168 [INFO] 17872 6284 C:\Users\vanis\.virtualenvs\manager_api-qKfrZB-Q\lib\site-packages\django\utils\autoreload.py:617 Watching for file changes with StatReloader
2022-06-04 23:30:17,124 [INFO] 17872 24668 C:\Users\vanis\OneDrive\デスクトップ\workspace\03_projects\01_private\manager\manager_api\manager_api_app\views\body_weight_view.py:21 result_data:[{'users': 'tetsuya'}, {'users': 'taro'}]
2022-06-04 23:30:17,125 [INFO] 17872 24668 C:\Users\vanis\.virtualenvs\manager_api-qKfrZB-Q\lib\site-packages\django\core\servers\basehttp.py:157 "GET /manager_api_app/history_user/ HTTP/1.1" 200 89
2022-06-04 23:30:18,122 [INFO] 17872 9888 C:\Users\vanis\OneDrive\デスクトップ\workspace\03_projects\01_private\manager\manager_api\manager_api_app\views\body_weight_view.py:35 request.GET:<QueryDict: {}>
2022-06-04 23:30:18,257 [ERROR] 17872 9888 C:\Users\vanis\.virtualenvs\manager_api-qKfrZB-Q\lib\site-packages\django\utils\log.py:224 Internal Server Error: /manager_api_app/body_weight/
Traceback (most recent call last):
  File "C:\Users\vanis\.virtualenvs\manager_api-qKfrZB-Q\lib\site-packages\django\core\handlers\exception.py", line 47, in inner
    response = get_response(request)
  File "C:\Users\vanis\.virtualenvs\manager_api-qKfrZB-Q\lib\site-packages\django\core\handlers\base.py", line 181, in _get_response
    response = wrapped_callback(request, *callback_args, **callback_kwargs)
  File "C:\Users\vanis\.virtualenvs\manager_api-qKfrZB-Q\lib\site-packages\django\views\decorators\csrf.py", line 54, in wrapped_view
    return view_func(*args, **kwargs)
  File "C:\Users\vanis\.virtualenvs\manager_api-qKfrZB-Q\lib\site-packages\django\views\generic\base.py", line 70, in view
    return self.dispatch(request, *args, **kwargs)
  File "C:\Users\vanis\.virtualenvs\manager_api-qKfrZB-Q\lib\site-packages\rest_framework\views.py", line 509, in dispatch
    response = self.handle_exception(exc)
  File "C:\Users\vanis\.virtualenvs\manager_api-qKfrZB-Q\lib\site-packages\rest_framework\views.py", line 469, in handle_exception
    self.raise_uncaught_exception(exc)
  File "C:\Users\vanis\.virtualenvs\manager_api-qKfrZB-Q\lib\site-packages\rest_framework\views.py", line 480, in raise_uncaught_exception
    raise exc
  File "C:\Users\vanis\.virtualenvs\manager_api-qKfrZB-Q\lib\site-packages\rest_framework\views.py", line 506, in dispatch
    response = handler(request, *args, **kwargs)
  File "C:\Users\vanis\.virtualenvs\manager_api-qKfrZB-Q\lib\site-packages\rest_framework\decorators.py", line 50, in handler
    return func(*args, **kwargs)
  File "C:\Users\vanis\OneDrive\デスクトップ\workspace\03_projects\01_private\manager\manager_api\manager_api_app\views\body_weight_view.py", line 39, in get_weight
    response_body=weight_list,
NameError: name 'weight_list' is not defined
2022-06-04 23:30:18,275 [ERROR] 17872 9888 C:\Users\vanis\.virtualenvs\manager_api-qKfrZB-Q\lib\site-packages\django\core\servers\basehttp.py:157 "POST /manager_api_app/body_weight/ HTTP/1.1" 500 100907
2022-06-04 23:30:29,249 [INFO] 17872 6284 C:\Users\vanis\.virtualenvs\manager_api-qKfrZB-Q\lib\site-packages\django\utils\autoreload.py:240 C:\Users\vanis\OneDrive\デスクトップ\workspace\03_projects\01_private\manager\manager_api\manager_api_app\views\body_weight_view.py changed, reloading.
2022-06-04 23:30:30,085 [INFO] 7860 23324 C:\Users\vanis\.virtualenvs\manager_api-qKfrZB-Q\lib\site-packages\django\utils\autoreload.py:617 Watching for file changes with StatReloader
2022-06-04 23:30:30,220 [INFO] 7860 22376 C:\Users\vanis\OneDrive\デスクトップ\workspace\03_projects\01_private\manager\manager_api\manager_api_app\views\body_weight_view.py:21 result_data:[{'users': 'tetsuya'}, {'users': 'taro'}]
2022-06-04 23:30:30,221 [INFO] 7860 22376 C:\Users\vanis\.virtualenvs\manager_api-qKfrZB-Q\lib\site-packages\django\core\servers\basehttp.py:157 "GET /manager_api_app/history_user/ HTTP/1.1" 200 89
2022-06-04 23:30:31,411 [INFO] 7860 1624 C:\Users\vanis\OneDrive\デスクトップ\workspace\03_projects\01_private\manager\manager_api\manager_api_app\views\body_weight_view.py:35 request:<rest_framework.request.Request: POST '/manager_api_app/body_weight/'>
2022-06-04 23:30:31,513 [ERROR] 7860 1624 C:\Users\vanis\.virtualenvs\manager_api-qKfrZB-Q\lib\site-packages\django\utils\log.py:224 Internal Server Error: /manager_api_app/body_weight/
Traceback (most recent call last):
  File "C:\Users\vanis\.virtualenvs\manager_api-qKfrZB-Q\lib\site-packages\django\core\handlers\exception.py", line 47, in inner
    response = get_response(request)
  File "C:\Users\vanis\.virtualenvs\manager_api-qKfrZB-Q\lib\site-packages\django\core\handlers\base.py", line 181, in _get_response
    response = wrapped_callback(request, *callback_args, **callback_kwargs)
  File "C:\Users\vanis\.virtualenvs\manager_api-qKfrZB-Q\lib\site-packages\django\views\decorators\csrf.py", line 54, in wrapped_view
    return view_func(*args, **kwargs)
  File "C:\Users\vanis\.virtualenvs\manager_api-qKfrZB-Q\lib\site-packages\django\views\generic\base.py", line 70, in view
    return self.dispatch(request, *args, **kwargs)
  File "C:\Users\vanis\.virtualenvs\manager_api-qKfrZB-Q\lib\site-packages\rest_framework\views.py", line 509, in dispatch
    response = self.handle_exception(exc)
  File "C:\Users\vanis\.virtualenvs\manager_api-qKfrZB-Q\lib\site-packages\rest_framework\views.py", line 469, in handle_exception
    self.raise_uncaught_exception(exc)
  File "C:\Users\vanis\.virtualenvs\manager_api-qKfrZB-Q\lib\site-packages\rest_framework\views.py", line 480, in raise_uncaught_exception
    raise exc
  File "C:\Users\vanis\.virtualenvs\manager_api-qKfrZB-Q\lib\site-packages\rest_framework\views.py", line 506, in dispatch
    response = handler(request, *args, **kwargs)
  File "C:\Users\vanis\.virtualenvs\manager_api-qKfrZB-Q\lib\site-packages\rest_framework\decorators.py", line 50, in handler
    return func(*args, **kwargs)
  File "C:\Users\vanis\OneDrive\デスクトップ\workspace\03_projects\01_private\manager\manager_api\manager_api_app\views\body_weight_view.py", line 39, in get_weight
    response_body=weight_list,
NameError: name 'weight_list' is not defined
2022-06-04 23:30:31,516 [ERROR] 7860 1624 C:\Users\vanis\.virtualenvs\manager_api-qKfrZB-Q\lib\site-packages\django\core\servers\basehttp.py:157 "POST /manager_api_app/body_weight/ HTTP/1.1" 500 100899
2022-06-04 23:32:31,909 [INFO] 7860 23324 C:\Users\vanis\.virtualenvs\manager_api-qKfrZB-Q\lib\site-packages\django\utils\autoreload.py:240 C:\Users\vanis\OneDrive\デスクトップ\workspace\03_projects\01_private\manager\manager_api\manager_api_app\views\body_weight_view.py changed, reloading.
2022-06-04 23:32:32,877 [INFO] 11300 15820 C:\Users\vanis\.virtualenvs\manager_api-qKfrZB-Q\lib\site-packages\django\utils\autoreload.py:617 Watching for file changes with StatReloader
2022-06-04 23:32:37,351 [INFO] 11300 15820 C:\Users\vanis\.virtualenvs\manager_api-qKfrZB-Q\lib\site-packages\django\utils\autoreload.py:240 C:\Users\vanis\OneDrive\デスクトップ\workspace\03_projects\01_private\manager\manager_api\manager_api_app\views\body_weight_view.py changed, reloading.
2022-06-04 23:32:38,150 [INFO] 7452 13952 C:\Users\vanis\.virtualenvs\manager_api-qKfrZB-Q\lib\site-packages\django\utils\autoreload.py:617 Watching for file changes with StatReloader
2022-06-04 23:32:39,644 [INFO] 7452 24376 C:\Users\vanis\OneDrive\デスクトップ\workspace\03_projects\01_private\manager\manager_api\manager_api_app\views\body_weight_view.py:35 weight_list:<QuerySet [<BodyWeight: BodyWeight object (1)>]>
2022-06-04 23:32:39,759 [ERROR] 7452 24376 C:\Users\vanis\.virtualenvs\manager_api-qKfrZB-Q\lib\site-packages\django\utils\log.py:224 Internal Server Error: /manager_api_app/body_weight/
Traceback (most recent call last):
  File "C:\Users\vanis\.virtualenvs\manager_api-qKfrZB-Q\lib\site-packages\django\core\handlers\exception.py", line 47, in inner
    response = get_response(request)
  File "C:\Users\vanis\.virtualenvs\manager_api-qKfrZB-Q\lib\site-packages\django\core\handlers\base.py", line 204, in _get_response
    response = response.render()
  File "C:\Users\vanis\.virtualenvs\manager_api-qKfrZB-Q\lib\site-packages\django\template\response.py", line 105, in render
    self.content = self.rendered_content
  File "C:\Users\vanis\.virtualenvs\manager_api-qKfrZB-Q\lib\site-packages\rest_framework\response.py", line 70, in rendered_content
    ret = renderer.render(self.data, accepted_media_type, context)
  File "C:\Users\vanis\.virtualenvs\manager_api-qKfrZB-Q\lib\site-packages\rest_framework\renderers.py", line 100, in render
    ret = json.dumps(
  File "C:\Users\vanis\.virtualenvs\manager_api-qKfrZB-Q\lib\site-packages\rest_framework\utils\json.py", line 25, in dumps
    return json.dumps(*args, **kwargs)
  File "C:\Users\vanis\AppData\Local\Programs\Python\Python310\lib\json\__init__.py", line 238, in dumps
    **kw).encode(obj)
  File "C:\Users\vanis\AppData\Local\Programs\Python\Python310\lib\json\encoder.py", line 199, in encode
    chunks = self.iterencode(o, _one_shot=True)
  File "C:\Users\vanis\AppData\Local\Programs\Python\Python310\lib\json\encoder.py", line 257, in iterencode
    return _iterencode(o, 0)
  File "C:\Users\vanis\.virtualenvs\manager_api-qKfrZB-Q\lib\site-packages\rest_framework\utils\encoders.py", line 67, in default
    return super().default(obj)
  File "C:\Users\vanis\AppData\Local\Programs\Python\Python310\lib\json\encoder.py", line 179, in default
    raise TypeError(f'Object of type {o.__class__.__name__} '
TypeError: Object of type BodyWeight is not JSON serializable
2022-06-04 23:32:39,764 [ERROR] 7452 24376 C:\Users\vanis\.virtualenvs\manager_api-qKfrZB-Q\lib\site-packages\django\core\servers\basehttp.py:157 "POST /manager_api_app/body_weight/ HTTP/1.1" 500 106133
2022-06-04 23:33:16,969 [INFO] 7452 13952 C:\Users\vanis\.virtualenvs\manager_api-qKfrZB-Q\lib\site-packages\django\utils\autoreload.py:240 C:\Users\vanis\OneDrive\デスクトップ\workspace\03_projects\01_private\manager\manager_api\manager_api_app\views\body_weight_view.py changed, reloading.
2022-06-04 23:33:17,729 [INFO] 19780 17752 C:\Users\vanis\.virtualenvs\manager_api-qKfrZB-Q\lib\site-packages\django\utils\autoreload.py:617 Watching for file changes with StatReloader
2022-06-04 23:33:18,248 [INFO] 19780 22168 C:\Users\vanis\OneDrive\デスクトップ\workspace\03_projects\01_private\manager\manager_api\manager_api_app\views\body_weight_view.py:21 result_data:[{'users': 'tetsuya'}, {'users': 'taro'}]
2022-06-04 23:33:18,249 [INFO] 19780 22168 C:\Users\vanis\.virtualenvs\manager_api-qKfrZB-Q\lib\site-packages\django\core\servers\basehttp.py:157 "GET /manager_api_app/history_user/ HTTP/1.1" 200 89
2022-06-04 23:33:20,212 [ERROR] 19780 11804 C:\Users\vanis\.virtualenvs\manager_api-qKfrZB-Q\lib\site-packages\django\utils\log.py:224 Internal Server Error: /manager_api_app/body_weight/
Traceback (most recent call last):
  File "C:\Users\vanis\.virtualenvs\manager_api-qKfrZB-Q\lib\site-packages\rest_framework\request.py", line 416, in __getattr__
    return getattr(self._request, attr)
AttributeError: 'WSGIRequest' object has no attribute 'user_name'

During handling of the above exception, another exception occurred:

Traceback (most recent call last):
  File "C:\Users\vanis\.virtualenvs\manager_api-qKfrZB-Q\lib\site-packages\django\core\handlers\exception.py", line 47, in inner
    response = get_response(request)
  File "C:\Users\vanis\.virtualenvs\manager_api-qKfrZB-Q\lib\site-packages\django\core\handlers\base.py", line 181, in _get_response
    response = wrapped_callback(request, *callback_args, **callback_kwargs)
  File "C:\Users\vanis\.virtualenvs\manager_api-qKfrZB-Q\lib\site-packages\django\views\decorators\csrf.py", line 54, in wrapped_view
    return view_func(*args, **kwargs)
  File "C:\Users\vanis\.virtualenvs\manager_api-qKfrZB-Q\lib\site-packages\django\views\generic\base.py", line 70, in view
    return self.dispatch(request, *args, **kwargs)
  File "C:\Users\vanis\.virtualenvs\manager_api-qKfrZB-Q\lib\site-packages\rest_framework\views.py", line 509, in dispatch
    response = self.handle_exception(exc)
  File "C:\Users\vanis\.virtualenvs\manager_api-qKfrZB-Q\lib\site-packages\rest_framework\views.py", line 469, in handle_exception
    self.raise_uncaught_exception(exc)
  File "C:\Users\vanis\.virtualenvs\manager_api-qKfrZB-Q\lib\site-packages\rest_framework\views.py", line 480, in raise_uncaught_exception
    raise exc
  File "C:\Users\vanis\.virtualenvs\manager_api-qKfrZB-Q\lib\site-packages\rest_framework\views.py", line 506, in dispatch
    response = handler(request, *args, **kwargs)
  File "C:\Users\vanis\.virtualenvs\manager_api-qKfrZB-Q\lib\site-packages\rest_framework\decorators.py", line 50, in handler
    return func(*args, **kwargs)
  File "C:\Users\vanis\OneDrive\デスクトップ\workspace\03_projects\01_private\manager\manager_api\manager_api_app\views\body_weight_view.py", line 33, in get_weight
    weight_list = BodyWeight.objects.get(users=request.user_name, delete_flag=0)
  File "C:\Users\vanis\.virtualenvs\manager_api-qKfrZB-Q\lib\site-packages\rest_framework\request.py", line 418, in __getattr__
    return self.__getattribute__(attr)
AttributeError: 'Request' object has no attribute 'user_name'
2022-06-04 23:33:20,216 [ERROR] 19780 11804 C:\Users\vanis\.virtualenvs\manager_api-qKfrZB-Q\lib\site-packages\django\core\servers\basehttp.py:157 "POST /manager_api_app/body_weight/ HTTP/1.1" 500 109437
2022-06-04 23:33:47,337 [INFO] 19780 17752 C:\Users\vanis\.virtualenvs\manager_api-qKfrZB-Q\lib\site-packages\django\utils\autoreload.py:240 C:\Users\vanis\OneDrive\デスクトップ\workspace\03_projects\01_private\manager\manager_api\manager_api_app\views\body_weight_view.py changed, reloading.
2022-06-04 23:33:48,116 [INFO] 10860 21376 C:\Users\vanis\.virtualenvs\manager_api-qKfrZB-Q\lib\site-packages\django\utils\autoreload.py:617 Watching for file changes with StatReloader
2022-06-04 23:33:48,373 [INFO] 10860 8464 C:\Users\vanis\OneDrive\デスクトップ\workspace\03_projects\01_private\manager\manager_api\manager_api_app\views\body_weight_view.py:21 result_data:[{'users': 'tetsuya'}, {'users': 'taro'}]
2022-06-04 23:33:48,374 [INFO] 10860 8464 C:\Users\vanis\.virtualenvs\manager_api-qKfrZB-Q\lib\site-packages\django\core\servers\basehttp.py:157 "GET /manager_api_app/history_user/ HTTP/1.1" 200 89
2022-06-04 23:33:49,441 [ERROR] 10860 24684 C:\Users\vanis\.virtualenvs\manager_api-qKfrZB-Q\lib\site-packages\django\utils\log.py:224 Internal Server Error: /manager_api_app/body_weight/
Traceback (most recent call last):
  File "C:\Users\vanis\.virtualenvs\manager_api-qKfrZB-Q\lib\site-packages\django\core\handlers\exception.py", line 47, in inner
    response = get_response(request)
  File "C:\Users\vanis\.virtualenvs\manager_api-qKfrZB-Q\lib\site-packages\django\core\handlers\base.py", line 181, in _get_response
    response = wrapped_callback(request, *callback_args, **callback_kwargs)
  File "C:\Users\vanis\.virtualenvs\manager_api-qKfrZB-Q\lib\site-packages\django\views\decorators\csrf.py", line 54, in wrapped_view
    return view_func(*args, **kwargs)
  File "C:\Users\vanis\.virtualenvs\manager_api-qKfrZB-Q\lib\site-packages\django\views\generic\base.py", line 70, in view
    return self.dispatch(request, *args, **kwargs)
  File "C:\Users\vanis\.virtualenvs\manager_api-qKfrZB-Q\lib\site-packages\rest_framework\views.py", line 509, in dispatch
    response = self.handle_exception(exc)
  File "C:\Users\vanis\.virtualenvs\manager_api-qKfrZB-Q\lib\site-packages\rest_framework\views.py", line 469, in handle_exception
    self.raise_uncaught_exception(exc)
  File "C:\Users\vanis\.virtualenvs\manager_api-qKfrZB-Q\lib\site-packages\rest_framework\views.py", line 480, in raise_uncaught_exception
    raise exc
  File "C:\Users\vanis\.virtualenvs\manager_api-qKfrZB-Q\lib\site-packages\rest_framework\views.py", line 506, in dispatch
    response = handler(request, *args, **kwargs)
  File "C:\Users\vanis\.virtualenvs\manager_api-qKfrZB-Q\lib\site-packages\rest_framework\decorators.py", line 50, in handler
    return func(*args, **kwargs)
TypeError: BodyWeightView.get_weight() missing 1 required positional argument: 'request'
2022-06-04 23:33:49,442 [ERROR] 10860 24684 C:\Users\vanis\.virtualenvs\manager_api-qKfrZB-Q\lib\site-packages\django\core\servers\basehttp.py:157 "POST /manager_api_app/body_weight/ HTTP/1.1" 500 97484
2022-06-04 23:35:32,823 [ERROR] 10860 24684 C:\Users\vanis\.virtualenvs\manager_api-qKfrZB-Q\lib\site-packages\django\utils\log.py:224 Internal Server Error: /manager_api_app/body_weight/
Traceback (most recent call last):
  File "C:\Users\vanis\.virtualenvs\manager_api-qKfrZB-Q\lib\site-packages\django\core\handlers\exception.py", line 47, in inner
    response = get_response(request)
  File "C:\Users\vanis\.virtualenvs\manager_api-qKfrZB-Q\lib\site-packages\django\core\handlers\base.py", line 181, in _get_response
    response = wrapped_callback(request, *callback_args, **callback_kwargs)
  File "C:\Users\vanis\.virtualenvs\manager_api-qKfrZB-Q\lib\site-packages\django\views\decorators\csrf.py", line 54, in wrapped_view
    return view_func(*args, **kwargs)
  File "C:\Users\vanis\.virtualenvs\manager_api-qKfrZB-Q\lib\site-packages\django\views\generic\base.py", line 70, in view
    return self.dispatch(request, *args, **kwargs)
  File "C:\Users\vanis\.virtualenvs\manager_api-qKfrZB-Q\lib\site-packages\rest_framework\views.py", line 509, in dispatch
    response = self.handle_exception(exc)
  File "C:\Users\vanis\.virtualenvs\manager_api-qKfrZB-Q\lib\site-packages\rest_framework\views.py", line 469, in handle_exception
    self.raise_uncaught_exception(exc)
  File "C:\Users\vanis\.virtualenvs\manager_api-qKfrZB-Q\lib\site-packages\rest_framework\views.py", line 480, in raise_uncaught_exception
    raise exc
  File "C:\Users\vanis\.virtualenvs\manager_api-qKfrZB-Q\lib\site-packages\rest_framework\views.py", line 506, in dispatch
    response = handler(request, *args, **kwargs)
  File "C:\Users\vanis\.virtualenvs\manager_api-qKfrZB-Q\lib\site-packages\rest_framework\decorators.py", line 50, in handler
    return func(*args, **kwargs)
TypeError: BodyWeightView.get_weight() missing 1 required positional argument: 'request'
2022-06-04 23:35:32,826 [ERROR] 10860 24684 C:\Users\vanis\.virtualenvs\manager_api-qKfrZB-Q\lib\site-packages\django\core\servers\basehttp.py:157 "POST /manager_api_app/body_weight/ HTTP/1.1" 500 97484
2022-06-04 23:35:38,596 [ERROR] 10860 24684 C:\Users\vanis\.virtualenvs\manager_api-qKfrZB-Q\lib\site-packages\django\utils\log.py:224 Internal Server Error: /manager_api_app/body_weight/
Traceback (most recent call last):
  File "C:\Users\vanis\.virtualenvs\manager_api-qKfrZB-Q\lib\site-packages\django\core\handlers\exception.py", line 47, in inner
    response = get_response(request)
  File "C:\Users\vanis\.virtualenvs\manager_api-qKfrZB-Q\lib\site-packages\django\core\handlers\base.py", line 181, in _get_response
    response = wrapped_callback(request, *callback_args, **callback_kwargs)
  File "C:\Users\vanis\.virtualenvs\manager_api-qKfrZB-Q\lib\site-packages\django\views\decorators\csrf.py", line 54, in wrapped_view
    return view_func(*args, **kwargs)
  File "C:\Users\vanis\.virtualenvs\manager_api-qKfrZB-Q\lib\site-packages\django\views\generic\base.py", line 70, in view
    return self.dispatch(request, *args, **kwargs)
  File "C:\Users\vanis\.virtualenvs\manager_api-qKfrZB-Q\lib\site-packages\rest_framework\views.py", line 509, in dispatch
    response = self.handle_exception(exc)
  File "C:\Users\vanis\.virtualenvs\manager_api-qKfrZB-Q\lib\site-packages\rest_framework\views.py", line 469, in handle_exception
    self.raise_uncaught_exception(exc)
  File "C:\Users\vanis\.virtualenvs\manager_api-qKfrZB-Q\lib\site-packages\rest_framework\views.py", line 480, in raise_uncaught_exception
    raise exc
  File "C:\Users\vanis\.virtualenvs\manager_api-qKfrZB-Q\lib\site-packages\rest_framework\views.py", line 506, in dispatch
    response = handler(request, *args, **kwargs)
  File "C:\Users\vanis\.virtualenvs\manager_api-qKfrZB-Q\lib\site-packages\rest_framework\decorators.py", line 50, in handler
    return func(*args, **kwargs)
TypeError: BodyWeightView.get_weight() missing 1 required positional argument: 'request'
2022-06-04 23:35:38,602 [INFO] 10860 8464 C:\Users\vanis\OneDrive\デスクトップ\workspace\03_projects\01_private\manager\manager_api\manager_api_app\views\body_weight_view.py:21 result_data:[{'users': 'tetsuya'}, {'users': 'taro'}]
2022-06-04 23:35:38,605 [INFO] 10860 8464 C:\Users\vanis\.virtualenvs\manager_api-qKfrZB-Q\lib\site-packages\django\core\servers\basehttp.py:157 "GET /manager_api_app/history_user/ HTTP/1.1" 200 89
2022-06-04 23:35:38,609 [ERROR] 10860 24684 C:\Users\vanis\.virtualenvs\manager_api-qKfrZB-Q\lib\site-packages\django\core\servers\basehttp.py:157 "POST /manager_api_app/body_weight/ HTTP/1.1" 500 97484
2022-06-04 23:35:39,367 [INFO] 10860 8464 C:\Users\vanis\OneDrive\デスクトップ\workspace\03_projects\01_private\manager\manager_api\manager_api_app\views\body_weight_view.py:21 result_data:[{'users': 'tetsuya'}, {'users': 'taro'}]
2022-06-04 23:35:39,383 [ERROR] 10860 24684 C:\Users\vanis\.virtualenvs\manager_api-qKfrZB-Q\lib\site-packages\django\utils\log.py:224 Internal Server Error: /manager_api_app/body_weight/
Traceback (most recent call last):
  File "C:\Users\vanis\.virtualenvs\manager_api-qKfrZB-Q\lib\site-packages\django\core\handlers\exception.py", line 47, in inner
    response = get_response(request)
  File "C:\Users\vanis\.virtualenvs\manager_api-qKfrZB-Q\lib\site-packages\django\core\handlers\base.py", line 181, in _get_response
    response = wrapped_callback(request, *callback_args, **callback_kwargs)
  File "C:\Users\vanis\.virtualenvs\manager_api-qKfrZB-Q\lib\site-packages\django\views\decorators\csrf.py", line 54, in wrapped_view
    return view_func(*args, **kwargs)
  File "C:\Users\vanis\.virtualenvs\manager_api-qKfrZB-Q\lib\site-packages\django\views\generic\base.py", line 70, in view
    return self.dispatch(request, *args, **kwargs)
  File "C:\Users\vanis\.virtualenvs\manager_api-qKfrZB-Q\lib\site-packages\rest_framework\views.py", line 509, in dispatch
    response = self.handle_exception(exc)
  File "C:\Users\vanis\.virtualenvs\manager_api-qKfrZB-Q\lib\site-packages\rest_framework\views.py", line 469, in handle_exception
    self.raise_uncaught_exception(exc)
  File "C:\Users\vanis\.virtualenvs\manager_api-qKfrZB-Q\lib\site-packages\rest_framework\views.py", line 480, in raise_uncaught_exception
    raise exc
  File "C:\Users\vanis\.virtualenvs\manager_api-qKfrZB-Q\lib\site-packages\rest_framework\views.py", line 506, in dispatch
    response = handler(request, *args, **kwargs)
  File "C:\Users\vanis\.virtualenvs\manager_api-qKfrZB-Q\lib\site-packages\rest_framework\decorators.py", line 50, in handler
    return func(*args, **kwargs)
TypeError: BodyWeightView.get_weight() missing 1 required positional argument: 'request'
2022-06-04 23:35:39,384 [INFO] 10860 8464 C:\Users\vanis\.virtualenvs\manager_api-qKfrZB-Q\lib\site-packages\django\core\servers\basehttp.py:157 "GET /manager_api_app/history_user/ HTTP/1.1" 200 89
2022-06-04 23:35:39,387 [ERROR] 10860 24684 C:\Users\vanis\.virtualenvs\manager_api-qKfrZB-Q\lib\site-packages\django\core\servers\basehttp.py:157 "POST /manager_api_app/body_weight/ HTTP/1.1" 500 97484
2022-06-04 23:35:42,501 [INFO] 10860 8464 C:\Users\vanis\OneDrive\デスクトップ\workspace\03_projects\01_private\manager\manager_api\manager_api_app\views\body_weight_view.py:21 result_data:[{'users': 'tetsuya'}, {'users': 'taro'}]
2022-06-04 23:35:42,515 [ERROR] 10860 24684 C:\Users\vanis\.virtualenvs\manager_api-qKfrZB-Q\lib\site-packages\django\utils\log.py:224 Internal Server Error: /manager_api_app/body_weight/
Traceback (most recent call last):
  File "C:\Users\vanis\.virtualenvs\manager_api-qKfrZB-Q\lib\site-packages\django\core\handlers\exception.py", line 47, in inner
    response = get_response(request)
  File "C:\Users\vanis\.virtualenvs\manager_api-qKfrZB-Q\lib\site-packages\django\core\handlers\base.py", line 181, in _get_response
    response = wrapped_callback(request, *callback_args, **callback_kwargs)
  File "C:\Users\vanis\.virtualenvs\manager_api-qKfrZB-Q\lib\site-packages\django\views\decorators\csrf.py", line 54, in wrapped_view
    return view_func(*args, **kwargs)
  File "C:\Users\vanis\.virtualenvs\manager_api-qKfrZB-Q\lib\site-packages\django\views\generic\base.py", line 70, in view
    return self.dispatch(request, *args, **kwargs)
  File "C:\Users\vanis\.virtualenvs\manager_api-qKfrZB-Q\lib\site-packages\rest_framework\views.py", line 509, in dispatch
    response = self.handle_exception(exc)
  File "C:\Users\vanis\.virtualenvs\manager_api-qKfrZB-Q\lib\site-packages\rest_framework\views.py", line 469, in handle_exception
    self.raise_uncaught_exception(exc)
  File "C:\Users\vanis\.virtualenvs\manager_api-qKfrZB-Q\lib\site-packages\rest_framework\views.py", line 480, in raise_uncaught_exception
    raise exc
  File "C:\Users\vanis\.virtualenvs\manager_api-qKfrZB-Q\lib\site-packages\rest_framework\views.py", line 506, in dispatch
    response = handler(request, *args, **kwargs)
  File "C:\Users\vanis\.virtualenvs\manager_api-qKfrZB-Q\lib\site-packages\rest_framework\decorators.py", line 50, in handler
    return func(*args, **kwargs)
TypeError: BodyWeightView.get_weight() missing 1 required positional argument: 'request'
2022-06-04 23:35:42,516 [INFO] 10860 8464 C:\Users\vanis\.virtualenvs\manager_api-qKfrZB-Q\lib\site-packages\django\core\servers\basehttp.py:157 "GET /manager_api_app/history_user/ HTTP/1.1" 200 89
2022-06-04 23:35:42,518 [ERROR] 10860 24684 C:\Users\vanis\.virtualenvs\manager_api-qKfrZB-Q\lib\site-packages\django\core\servers\basehttp.py:157 "POST /manager_api_app/body_weight/ HTTP/1.1" 500 97484
2022-06-04 23:35:46,592 [INFO] 10860 8464 C:\Users\vanis\OneDrive\デスクトップ\workspace\03_projects\01_private\manager\manager_api\manager_api_app\views\body_weight_view.py:21 result_data:[{'users': 'tetsuya'}, {'users': 'taro'}]
2022-06-04 23:35:46,600 [ERROR] 10860 24684 C:\Users\vanis\.virtualenvs\manager_api-qKfrZB-Q\lib\site-packages\django\utils\log.py:224 Internal Server Error: /manager_api_app/body_weight/
Traceback (most recent call last):
  File "C:\Users\vanis\.virtualenvs\manager_api-qKfrZB-Q\lib\site-packages\django\core\handlers\exception.py", line 47, in inner
    response = get_response(request)
  File "C:\Users\vanis\.virtualenvs\manager_api-qKfrZB-Q\lib\site-packages\django\core\handlers\base.py", line 181, in _get_response
    response = wrapped_callback(request, *callback_args, **callback_kwargs)
  File "C:\Users\vanis\.virtualenvs\manager_api-qKfrZB-Q\lib\site-packages\django\views\decorators\csrf.py", line 54, in wrapped_view
    return view_func(*args, **kwargs)
  File "C:\Users\vanis\.virtualenvs\manager_api-qKfrZB-Q\lib\site-packages\django\views\generic\base.py", line 70, in view
    return self.dispatch(request, *args, **kwargs)
  File "C:\Users\vanis\.virtualenvs\manager_api-qKfrZB-Q\lib\site-packages\rest_framework\views.py", line 509, in dispatch
    response = self.handle_exception(exc)
  File "C:\Users\vanis\.virtualenvs\manager_api-qKfrZB-Q\lib\site-packages\rest_framework\views.py", line 469, in handle_exception
    self.raise_uncaught_exception(exc)
  File "C:\Users\vanis\.virtualenvs\manager_api-qKfrZB-Q\lib\site-packages\rest_framework\views.py", line 480, in raise_uncaught_exception
    raise exc
  File "C:\Users\vanis\.virtualenvs\manager_api-qKfrZB-Q\lib\site-packages\rest_framework\views.py", line 506, in dispatch
    response = handler(request, *args, **kwargs)
  File "C:\Users\vanis\.virtualenvs\manager_api-qKfrZB-Q\lib\site-packages\rest_framework\decorators.py", line 50, in handler
    return func(*args, **kwargs)
TypeError: BodyWeightView.get_weight() missing 1 required positional argument: 'request'
2022-06-04 23:35:46,600 [INFO] 10860 8464 C:\Users\vanis\.virtualenvs\manager_api-qKfrZB-Q\lib\site-packages\django\core\servers\basehttp.py:157 "GET /manager_api_app/history_user/ HTTP/1.1" 200 89
2022-06-04 23:35:46,602 [ERROR] 10860 24684 C:\Users\vanis\.virtualenvs\manager_api-qKfrZB-Q\lib\site-packages\django\core\servers\basehttp.py:157 "POST /manager_api_app/body_weight/ HTTP/1.1" 500 97484
2022-06-04 23:43:10,852 [INFO] 10860 21376 C:\Users\vanis\.virtualenvs\manager_api-qKfrZB-Q\lib\site-packages\django\utils\autoreload.py:240 C:\Users\vanis\OneDrive\デスクトップ\workspace\03_projects\01_private\manager\manager_api\manager_api_app\models\body_weight.py changed, reloading.
2022-06-04 23:43:11,567 [INFO] 21256 2528 C:\Users\vanis\.virtualenvs\manager_api-qKfrZB-Q\lib\site-packages\django\utils\autoreload.py:617 Watching for file changes with StatReloader
2022-06-04 23:43:23,124 [INFO] 11004 14060 C:\Users\vanis\.virtualenvs\manager_api-qKfrZB-Q\lib\site-packages\django\utils\autoreload.py:617 Watching for file changes with StatReloader
2022-06-04 23:43:31,693 [INFO] 11004 14060 C:\Users\vanis\.virtualenvs\manager_api-qKfrZB-Q\lib\site-packages\django\utils\autoreload.py:240 C:\Users\vanis\OneDrive\デスクトップ\workspace\03_projects\01_private\manager\manager_api\manager_api_app\views\body_weight_view.py changed, reloading.
2022-06-04 23:43:32,441 [INFO] 18200 16480 C:\Users\vanis\.virtualenvs\manager_api-qKfrZB-Q\lib\site-packages\django\utils\autoreload.py:617 Watching for file changes with StatReloader
2022-06-05 00:04:03,764 [INFO] 21228 20840 C:\Users\vanis\.virtualenvs\manager_api-qKfrZB-Q\lib\site-packages\django\utils\autoreload.py:617 Watching for file changes with StatReloader
2022-06-05 00:04:20,308 [INFO] 21228 20840 C:\Users\vanis\.virtualenvs\manager_api-qKfrZB-Q\lib\site-packages\django\utils\autoreload.py:240 C:\Users\vanis\OneDrive\デスクトップ\workspace\03_projects\01_private\manager\manager_api\manager_api_app\models\__init__.py changed, reloading.
2022-06-05 00:04:20,996 [INFO] 25556 22152 C:\Users\vanis\.virtualenvs\manager_api-qKfrZB-Q\lib\site-packages\django\utils\autoreload.py:617 Watching for file changes with StatReloader
2022-06-05 00:04:51,901 [INFO] 25556 22152 C:\Users\vanis\.virtualenvs\manager_api-qKfrZB-Q\lib\site-packages\django\utils\autoreload.py:240 C:\Users\vanis\OneDrive\デスクトップ\workspace\03_projects\01_private\manager\manager_api\manager_api_app\admin.py changed, reloading.
2022-06-05 00:04:52,612 [INFO] 13264 17944 C:\Users\vanis\.virtualenvs\manager_api-qKfrZB-Q\lib\site-packages\django\utils\autoreload.py:617 Watching for file changes with StatReloader
2022-06-05 00:06:42,352 [INFO] 13264 17944 C:\Users\vanis\.virtualenvs\manager_api-qKfrZB-Q\lib\site-packages\django\utils\autoreload.py:240 C:\Users\vanis\OneDrive\デスクトップ\workspace\03_projects\01_private\manager\manager_api\manager_api_app\urls.py changed, reloading.
2022-06-05 00:06:43,074 [INFO] 16272 16436 C:\Users\vanis\.virtualenvs\manager_api-qKfrZB-Q\lib\site-packages\django\utils\autoreload.py:617 Watching for file changes with StatReloader
2022-06-05 00:07:29,778 [INFO] 16272 16436 C:\Users\vanis\.virtualenvs\manager_api-qKfrZB-Q\lib\site-packages\django\utils\autoreload.py:240 C:\Users\vanis\OneDrive\デスクトップ\workspace\03_projects\01_private\manager\manager_api\manager_api_app\views\party_register_view.py changed, reloading.
2022-06-05 00:07:30,484 [INFO] 21724 5324 C:\Users\vanis\.virtualenvs\manager_api-qKfrZB-Q\lib\site-packages\django\utils\autoreload.py:617 Watching for file changes with StatReloader
2022-06-05 00:09:40,103 [INFO] 24896 8268 C:\Users\vanis\.virtualenvs\manager_api-qKfrZB-Q\lib\site-packages\django\utils\autoreload.py:617 Watching for file changes with StatReloader
2022-06-05 00:10:31,277 [INFO] 24896 8268 C:\Users\vanis\.virtualenvs\manager_api-qKfrZB-Q\lib\site-packages\django\utils\autoreload.py:240 C:\Users\vanis\OneDrive\デスクトップ\workspace\03_projects\01_private\manager\manager_api\manager_api_app\urls.py changed, reloading.
2022-06-05 00:10:31,976 [INFO] 13248 24812 C:\Users\vanis\.virtualenvs\manager_api-qKfrZB-Q\lib\site-packages\django\utils\autoreload.py:617 Watching for file changes with StatReloader
2022-06-05 00:10:40,607 [INFO] 13248 24812 C:\Users\vanis\.virtualenvs\manager_api-qKfrZB-Q\lib\site-packages\django\utils\autoreload.py:240 C:\Users\vanis\OneDrive\デスクトップ\workspace\03_projects\01_private\manager\manager_api\manager_api\urls.py changed, reloading.
2022-06-05 00:10:41,331 [INFO] 21212 21432 C:\Users\vanis\.virtualenvs\manager_api-qKfrZB-Q\lib\site-packages\django\utils\autoreload.py:617 Watching for file changes with StatReloader
